Workbook
Name A: 'KW 05-08'!#REF!
Name A: 'KW 09-12'!#REF!
Name A: 'KW 13-16'!#REF!
Name A: 'KW 17-20'!#REF!
Name A: 'KW 21-24'!#REF!
Name A: 'KW 25-28'!#REF!
Name A: 'KW 29-32'!#REF!
Name A: 'KW 33-36'!#REF!
Name A: 'KW 37-40'!#REF!
Name A: 'KW 41-44'!#REF!
Name A: 'KW 45-48'!#REF!
Name A: 'KW 49-52'!#REF!
Name A: 'KW 01-04'!#REF!
Name AHG: 'KW 05-08'!#REF!
Name AHG: 'KW 09-12'!#REF!
Name AHG: 'KW 13-16'!#REF!
Name AHG: 'KW 17-20'!#REF!
Name AHG: 'KW 21-24'!#REF!
Name AHG: 'KW 25-28'!#REF!
Name AHG: 'KW 29-32'!#REF!
Name AHG: 'KW 33-36'!#REF!
Name AHG: 'KW 37-40'!#REF!
Name AHG: 'KW 41-44'!#REF!
Name AHG: 'KW 45-48'!#REF!
Name AHG: 'KW 49-52'!#REF!
Name AHG: 'KW 01-04'!#REF!
Name Gerd: 'KW 05-08'!#REF!
Name Gerd: 'KW 09-12'!#REF!
Name Gerd: 'KW 13-16'!#REF!
Name Gerd: 'KW 17-20'!#REF!
Name Gerd: 'KW 21-24'!#REF!
Name Gerd: 'KW 25-28'!#REF!
Name Gerd: 'KW 29-32'!#REF!
Name Gerd: 'KW 33-36'!#REF!
Name Gerd: 'KW 37-40'!#REF!
Name Gerd: 'KW 41-44'!#REF!
Name Gerd: 'KW 45-48'!#REF!
Name Gerd: 'KW 49-52'!#REF!
Name Gerd: 'KW 01-04'!#REF!
Name Heiko: 'KW 05-08'!#REF!
Name Heiko: 'KW 09-12'!#REF!
Name Heiko: 'KW 13-16'!#REF!
Name Heiko: 'KW 17-20'!#REF!
Name Heiko: 'KW 21-24'!#REF!
Name Heiko: 'KW 25-28'!#REF!
Name Heiko: 'KW 29-32'!#REF!
Name Heiko: 'KW 33-36'!#REF!
Name Heiko: 'KW 37-40'!#REF!
Name Heiko: 'KW 41-44'!#REF!
Name Heiko: 'KW 45-48'!#REF!
Name Heiko: 'KW 49-52'!#REF!
Name Heiko: 'KW 01-04'!#REF!
Name IstArbeitszeit: 'KW 05-08'!#REF!
Name IstArbeitszeit: 'KW 09-12'!#REF!
Name IstArbeitszeit: 'KW 13-16'!#REF!
Name IstArbeitszeit: 'KW 17-20'!#REF!
Name IstArbeitszeit: 'KW 21-24'!#REF!
Name IstArbeitszeit: 'KW 25-28'!#REF!
Name IstArbeitszeit: 'KW 29-32'!#REF!
Name IstArbeitszeit: 'KW 33-36'!#REF!

Sheet Stammangaben
A1: Personalangaben
A3: Name, Vorname
A4: Einrichtung
A5: Arbeitsumfang in Prozent | E5: 100
A6: Stundenumpfang in Stunden:Minuten | E6: 1.625
A7: Alternativer Stundenumpfang (St:Min) | E7: =(E6/E5)*C5 -> 0
A8: Ferienbetreuung Ja/Nein
A9: Arbeitstage/ Woche
A10: Überstunden letztes Jahr
A11: Übertrag letztes Blatt 4. Woche
A12: erster Montag im Jahr
C53: ja
C54: nein

Sheet KW 01-04
A1: Arbeitszeiterfassung (Freizeitausgleich) (Dieser Vordruck ist zu verwenden, wenn auf der Erklärung die Option "Freizeitausgleich" angekreuzt wurde)
A2: Name: | C2: =Stammangaben!$B$3 -> 0 | N2: TE | O2: =Stammangaben!B4 -> 0
A3: =IF(NOT(Stammangaben!C7=""),Stammangaben!C7,Stammangaben!C6) -> 0 | B3: Std / Woche | C3: gesamte Arbeitszeit | L3: VZ-Zeiten
C4: Übertrag der Gesamtstunden aus letztem Blatt | I4: =Stammangaben!C10 -> 0
C5: Übertrag der Mehrarbeit aus vierter Woche vom letzten Blatt | I5: =Stammangaben!C11 -> 0
K6: =IF(LEFT(I4,1)="-",RIGHT(I4,LEN(I4)-1),I4) -> 0 | L6: =IF(LEFT(K14,1)="-",RIGHT(K14,LEN(K14)-1),K14) -> 0 | M6: =IF(LEFT(K21,1)="-",RIGHT(K21,LEN(K21)-1),K21) -> 0 | N6: =IF(LEFT(K28,1)="-",RIGHT(K28,LEN(K28)-1),K28) -> 0
A7: KW | C7: Soll | D7: von | E7: bis | F7: Pause | G7: Ist | H7: U/K/F/AB | I7: Haben/ Woche | J7: AZ aus Bereit-schaft | K7: Haben ges. | L7: Soll | M7: Ist | N7: Haben | O7: außer Haus | P7: Begründung für Abweichung Soll / Ist bei VZ | Q7: bei relevanter Abweichung von der Soll-Arbeitszeit (= mehr als 30 min.) Begründung
B8: Mo | G8: =IF(OR(ISBLANK(D8),ISBLANK(E8)),0,E8-D8-F8) -> 0 | I8: =IF((G8-C8)<0,TEXT(C8-G8,"-[h]:mm"),G8-C8) -> 0 | N8: =IF((M8-L8)<0,TEXT(L8-M8,"-[h]:mm"),M8-L8) -> 0
A9: =A12+4 -> 4 | B9: Di | G9: =IF(OR(ISBLANK(D9),ISBLANK(E9)),0,E9-D9-F9) -> 0 | I9: =IF((G9-C9)<0,TEXT(C9-G9,"-[h]:mm"),G9-C9) -> 0 | N9: =IF((M9-L9)<0,TEXT(L9-M9,"-[h]:mm"),M9-L9) -> 0
B10: Mi | G10: =IF(OR(ISBLANK(D10),ISBLANK(E10)),0,E10-D10-F10) -> 0 | I10: =IF((G10-C10)<0,TEXT(C10-G10,"-[h]:mm"),G10-C10) -> 0 | N10: =IF((M10-L10)<0,TEXT(L10-M10,"-[h]:mm"),M10-L10) -> 0
A11: - | B11: Do | G11: =IF(OR(ISBLANK(D11),ISBLANK(E11)),0,E11-D11-F11) -> 0 | I11: =IF((G11-C11)<0,TEXT(C11-G11,"-[h]:mm"),G11-C11) -> 0 | N11: =IF((M11-L11)<0,TEXT(L11-M11,"-[h]:mm"),M11-L11) -> 0
A12: =Stammangaben!C12 -> 0 | B12: Fr | G12: =IF(OR(ISBLANK(D12),ISBLANK(E12)),0,E12-D12-F12) -> 0 | I12: =IF((G12-C12)<0,TEXT(C12-G12,"-[h]:mm"),G12-C12) -> 0 | N12: =IF((M12-L12)<0,TEXT(L12-M12,"-[h]:mm"),M12-L12) -> 0
B13: Sonst | G13: =IF(OR(ISBLANK(D13),ISBLANK(E13)),0,E13-D13-F13) -> 0 | I13: =IF((G13-C13)<0,TEXT(C13-G13,"-[h]:mm"),G13-C13) -> 0 | N13: =IF((M13-L13)<0,TEXT(L13-M13,"-[h]:mm"),M13-L13) -> 0
A14: 1 | B14: ∑ | C14: =SUM(C8:C13) -> 0 | F14: =SUM(F8:F13) -> 0 | G14: =SUM(G8:G13) -> 0 | I14: =IF((G14-C14+J14)<0,TEXT(C14-G14-J14,"-[h]:mm"),G14-C14+J14) -> 0 | J14: =SUM(J8:J13) -> 0 | K14: =IF(LEFT(I4,1)="-",IF((G14-C14+J14-K6)<0,TEXT(C14-G14-J14+K6,"-[hh]:mm"),G14-C14+J14-K6),IF((G14-C14+J14+K6)<0,TEXT(C14-G14+J14-K6,"-[hh]:mm"),G14-C14+J14+K6)) -> 0 | L14: =SUM(L8:L13) -> 0 | M14: =SUM(M8:M13) -> 0 | N14: =IF((M14-L14)<0,TEXT(L14-M14,"-[h]:mm"),M14-L14) -> 0
B15: Mo | G15: =IF(OR(ISBLANK(D15),ISBLANK(E15)),0,E15-D15-F15) -> 0 | I15: =IF((G15-C15)<0,TEXT(C15-G15,"-[h]:mm"),G15-C15) -> 0 | N15: =IF((M15-L15)<0,TEXT(L15-M15,"-[h]:mm"),M15-L15) -> 0
A16: =A19+4 -> 11 | B16: Di | G16: =IF(OR(ISBLANK(D16),ISBLANK(E16)),0,E16-D16-F16) -> 0 | I16: =IF((G16-C16)<0,TEXT(C16-G16,"-[h]:mm"),G16-C16) -> 0 | N16: =IF((M16-L16)<0,TEXT(L16-M16,"-[h]:mm"),M16-L16) -> 0
B17: Mi | G17: =IF(OR(ISBLANK(D17),ISBLANK(E17)),0,E17-D17-F17) -> 0 | I17: =IF((G17-C17)<0,TEXT(C17-G17,"-[h]:mm"),G17-C17) -> 0 | N17: =IF((M17-L17)<0,TEXT(L17-M17,"-[h]:mm"),M17-L17) -> 0
A18: - | B18: Do | G18: =IF(OR(ISBLANK(D18),ISBLANK(E18)),0,E18-D18-F18) -> 0 | I18: =IF((G18-C18)<0,TEXT(C18-G18,"-[h]:mm"),G18-C18) -> 0 | N18: =IF((M18-L18)<0,TEXT(L18-M18,"-[h]:mm"),M18-L18) -> 0
A19: =A9+3 -> 7 | B19: Fr | G19: =IF(OR(ISBLANK(D19),ISBLANK(E19)),0,E19-D19-F19) -> 0 | I19: =IF((G19-C19)<0,TEXT(C19-G19,"-[h]:mm"),G19-C19) -> 0 | N19: =IF((M19-L19)<0,TEXT(L19-M19,"-[h]:mm"),M19-L19) -> 0
B20: Sonst | G20: =E20-D20-F20 -> 0 | I20: =IF((G20-C20)<0,TEXT(C20-G20,"-[h]:mm"),G20-C20) -> 0 | N20: =IF((M20-L20)<0,TEXT(L20-M20,"-[h]:mm"),M20-L20) -> 0
A21: =IF(A14<>"",A14+1,"") -> 2 | B21: ∑ | C21: =SUM(C15:C20) -> 0 | F21: =SUM(F15:F20) -> 0 | G21: =SUM(G15:G20) -> 0 | I21: =IF((G21-C21+J21)<0,TEXT(C21-G21-J21,"-[h]:mm"),G21-C21+J21) -> 0 | J21: =SUM(J15:J20) -> 0 | K21: =IF(LEFT(K14,1)="-",IF((G21-C21+J21-L6)<0,TEXT(C21-G21-J21+L6,"-[hh]:mm"),G21-C21+J21-L6),IF((G21-C21+J21+L6)<0,TEXT(C21-G21+J21-L6,"-[hh]:mm"),G21-C21+J21+L6)) -> 0 | L21: =SUM(L15:L20) -> 0 | M21: =SUM(M15:M20) -> 0 | N21: =IF((M21-L21)<0,TEXT(L21-M21,"-[h]:mm"),M21-L21) -> 0
B22: Mo | G22: =IF(OR(ISBLANK(D22),ISBLANK(E22)),0,E22-D22-F22) -> 0 | I22: =IF((G22-C22)<0,TEXT(C22-G22,"-[h]:mm"),G22-C22) -> 0 | N22: =IF((M22-L22)<0,TEXT(L22-M22,"-[h]:mm"),M22-L22) -> 0
A23: =A26+4 -> 18 | B23: Di | G23: =IF(OR(ISBLANK(D23),ISBLANK(E23)),0,E23-D23-F23) -> 0 | I23: =IF((G23-C23)<0,TEXT(C23-G23,"-[h]:mm"),G23-C23) -> 0 | N23: =IF((M23-L23)<0,TEXT(L23-M23,"-[h]:mm"),M23-L23) -> 0
B24: Mi | G24: =IF(OR(ISBLANK(D24),ISBLANK(E24)),0,E24-D24-F24) -> 0 | I24: =IF((G24-C24)<0,TEXT(C24-G24,"-[h]:mm"),G24-C24) -> 0 | N24: =IF((M24-L24)<0,TEXT(L24-M24,"-[h]:mm"),M24-L24) -> 0
A25: - | B25: Do | G25: =IF(OR(ISBLANK(D25),ISBLANK(E25)),0,E25-D25-F25) -> 0 | I25: =IF((G25-C25)<0,TEXT(C25-G25,"-[h]:mm"),G25-C25) -> 0 | N25: =IF((M25-L25)<0,TEXT(L25-M25,"-[h]:mm"),M25-L25) -> 0
A26: =A16+3 -> 14 | B26: Fr | G26: =IF(OR(ISBLANK(D26),ISBLANK(E26)),0,E26-D26-F26) -> 0 | I26: =IF((G26-C26)<0,TEXT(C26-G26,"-[h]:mm"),G26-C26) -> 0 | N26: =IF((M26-L26)<0,TEXT(L26-M26,"-[h]:mm"),M26-L26) -> 0
B27: Sonst | G27: =IF(OR(ISBLANK(D27),ISBLANK(E27)),0,E27-D27-F27) -> 0 | I27: =IF((G27-C27)<0,TEXT(C27-G27,"-[h]:mm"),G27-C27) -> 0 | N27: =IF((M27-L27)<0,TEXT(L27-M27,"-[h]:mm"),M27-L27) -> 0
A28: =IF(A21<>"",A21+1,"") -> 3 | B28: ∑ | C28: =SUM(C22:C27) -> 0 | F28: =SUM(F22:F27) -> 0 | G28: =SUM(G22:G27) -> 0 | I28: =IF((G28-C28+J28)<0,TEXT(C28-G28-J28,"-[h]:mm"),G28-C28+J28) -> 0 | J28: =SUM(J22:J27) -> 0 | K28: =IF(LEFT(K21,1)="-",IF((G28-C28+J28-M6)<0,TEXT(C28-G28-J28+M6,"-[hh]:mm"),G28-C28+J28-M6),IF((G28-C28+J28+M6)<0,TEXT(C28-G28+J28-M6,"-[hh]:mm"),G28-C28+J28+M6)) -> 0 | L28: =SUM(L22:L27) -> 0 | M28: =SUM(M22:M27) -> 0 | N28: =IF((M28-L28)<0,TEXT(L28-M28,"-[h]:mm"),M28-L28) -> 0
B29: Mo | G29: =IF(OR(ISBLANK(D29),ISBLANK(E29)),0,E29-D29-F29) -> 0 | I29: =IF((G29-C29)<0,TEXT(C29-G29,"-[h]:mm"),G29-C29) -> 0 | N29: =IF((M29-L29)<0,TEXT(L29-M29,"-[h]:mm"),M29-L29) -> 0
A30: =A33+4 -> 25 | B30: Di | G30: =IF(OR(ISBLANK(D30),ISBLANK(E30)),0,E30-D30-F30) -> 0 | I30: =IF((G30-C30)<0,TEXT(C30-G30,"-[h]:mm"),G30-C30) -> 0 | N30: =IF((M30-L30)<0,TEXT(L30-M30,"-[h]:mm"),M30-L30) -> 0
B31: Mi | G31: =IF(OR(ISBLANK(D31),ISBLANK(E31)),0,E31-D31-F31) -> 0 | I31: =IF((G31-C31)<0,TEXT(C31-G31,"-[h]:mm"),G31-C31) -> 0 | N31: =IF((M31-L31)<0,TEXT(L31-M31,"-[h]:mm"),M31-L31) -> 0
A32: - | B32: Do | G32: =IF(OR(ISBLANK(D32),ISBLANK(E32)),0,E32-D32-F32) -> 0 | I32: =IF((G32-C32)<0,TEXT(C32-G32,"-[h]:mm"),G32-C32) -> 0 | N32: =IF((M32-L32)<0,TEXT(L32-M32,"-[h]:mm"),M32-L32) -> 0
A33: =A23+3 -> 21 | B33: Fr | G33: =IF(OR(ISBLANK(D33),ISBLANK(E33)),0,E33-D33-F33) -> 0 | I33: =IF((G33-C33)<0,TEXT(C33-G33,"-[hh]:mm"),G33-C33) -> 0 | N33: =IF((M33-L33)<0,TEXT(L33-M33,"-[h]:mm"),M33-L33) -> 0
B34: Sonst | G34: =IF(OR(ISBLANK(D34),ISBLANK(E34)),0,E34-D34-F34) -> 0 | I34: =IF((G34-C34)<0,TEXT(C34-G34,"-[hh]:mm"),G34-C34) -> 0 | N34: =IF((M34-L34)<0,TEXT(L34-M34,"-[h]:mm"),M34-L34) -> 0
A35: =IF(A28<>"",A28+1,"") -> 4 | B35: ∑ | C35: =SUM(C29:C34) -> 0 | F35: =SUM(F29:F34) -> 0 | G35: =SUM(G29:G34) -> 0 | I35: =IF((G35-C35+J35)<0,TEXT(C35-G35-J35,"-[h]:mm"),G35-C35+J35) -> 0 | J35: =SUM(J29:J34) -> 0 | K35: =IF(LEFT(K28,1)="-",IF((G35-C35+J35-N6)<0,TEXT(C35-G35-J35+N6,"-[hh]:mm"),G35-C35+J35-N6),IF((G35-C35+J35+N6)<0,TEXT(C35-G35+J35-N6,"-[hh]:mm"),G35-C35+J35+N6)) -> 0 | L35: =SUM(L29:L34) -> 0 | M35: =SUM(M29:M34) -> 0 | N35: =IF((M35-L35)<0,TEXT(L35-M35,"-[h]:mm"),M35-L35) -> 0
B36: ∑ | C36: =C14+C21+C28+C35 -> 0 | G36: =G14+G21+G28+G35 -> 0 | I36: =IF((G36-C36+J36)<0,TEXT(C36-G36-J36,"-[h]:mm"),G36-C36+J36) -> 0 | J36: =J14+J21+J28+J35 -> 0 | K36: =K35 -> 0 | N36: Gesamtstunden = Übertrag auf neues Blatt | Q36: =K36 -> 0
N37: Mehrarbeit in der vierten Woche = Übertrag auf neues Blatt | Q37: =I35 -> 0
A38: U | F38: =TODAY() -> 46019
A39: K | F39: Datum | M39: Unterschrift Mitarbeiter/-in
A40: F
...

Sheet KW 05-08
A1: Arbeitszeiterfassung (Freizeitausgleich) (Dieser Vordruck ist zu verwenden, wenn auf der Erklärung die Option "Freizeitausgleich" angekreuzt wurde)
A2: Name: | C2: =Stammangaben!$B$3 -> 0 | N2: TE | O2: =Stammangaben!B4 -> 0
A3: =IF(NOT(Stammangaben!C7=""),Stammangaben!C7,Stammangaben!C6) -> 0 | B3: Std / Woche | C3: gesamte Arbeitszeit | L3: VZ-Zeiten
C4: Übertrag der Gesamtstunden aus letztem Blatt | I4: ='KW 01-04'!K36 -> 0
C5: Übertrag der Mehrarbeit aus vierter Woche vom letzten Blatt | I5: ='KW 01-04'!I35 -> 0
K6: =IF(LEFT(I4,1)="-",RIGHT(I4,LEN(I4)-1),I4) -> 0 | L6: =IF(LEFT(K14,1)="-",RIGHT(K14,LEN(K14)-1),K14) -> 0 | M6: =IF(LEFT(K21,1)="-",RIGHT(K21,LEN(K21)-1),K21) -> 0 | N6: =IF(LEFT(K28,1)="-",RIGHT(K28,LEN(K28)-1),K28) -> 0
A7: KW | C7: Soll | D7: von | E7: bis | F7: Pause | G7: Ist | H7: U/K/F/AB | I7: Haben/ Woche | J7: AZ aus Bereit-schaft | K7: Haben ges. | L7: Soll | M7: Ist | N7: Haben | O7: außer Haus | P7: Begründung für Abweichung Soll / Ist bei VZ | Q7: bei relevanter Abweichung von der Soll-Arbeitszeit (= mehr als 30 min.) Begründung
B8: Mo | G8: =IF(OR(ISBLANK(D8),ISBLANK(E8)),0,E8-D8-F8) -> 0 | I8: =IF((G8-C8)<0,TEXT(C8-G8,"-[h]:mm"),G8-C8) -> 0 | N8: =IF((M8-L8)<0,TEXT(L8-M8,"-[h]:mm"),M8-L8) -> 0
A9: =A12+4 -> 32 | B9: Di | G9: =IF(OR(ISBLANK(D9),ISBLANK(E9)),0,E9-D9-F9) -> 0 | I9: =IF((G9-C9)<0,TEXT(C9-G9,"-[h]:mm"),G9-C9) -> 0 | N9: =IF((M9-L9)<0,TEXT(L9-M9,"-[h]:mm"),M9-L9) -> 0
B10: Mi | G10: =IF(OR(ISBLANK(D10),ISBLANK(E10)),0,E10-D10-F10) -> 0 | I10: =IF((G10-C10)<0,TEXT(C10-G10,"-[h]:mm"),G10-C10) -> 0 | N10: =IF((M10-L10)<0,TEXT(L10-M10,"-[h]:mm"),M10-L10) -> 0
A11: - | B11: Do | G11: =IF(OR(ISBLANK(D11),ISBLANK(E11)),0,E11-D11-F11) -> 0 | I11: =IF((G11-C11)<0,TEXT(C11-G11,"-[h]:mm"),G11-C11) -> 0 | N11: =IF((M11-L11)<0,TEXT(L11-M11,"-[h]:mm"),M11-L11) -> 0
A12: ='KW 01-04'!A30+3 -> 28 | B12: Fr | G12: =IF(OR(ISBLANK(D12),ISBLANK(E12)),0,E12-D12-F12) -> 0 | I12: =IF((G12-C12)<0,TEXT(C12-G12,"-[h]:mm"),G12-C12) -> 0 | N12: =IF((M12-L12)<0,TEXT(L12-M12,"-[h]:mm"),M12-L12) -> 0
B13: Sonst | G13: =IF(OR(ISBLANK(D13),ISBLANK(E13)),0,E13-D13-F13) -> 0 | I13: =IF((G13-C13)<0,TEXT(C13-G13,"-[h]:mm"),G13-C13) -> 0 | N13: =IF((M13-L13)<0,TEXT(L13-M13,"-[h]:mm"),M13-L13) -> 0
A14: ='KW 01-04'!A35+1 -> 5 | B14: ∑ | C14: =SUM(C8:C13) -> 0 | F14: =SUM(F8:F13) -> 0 | G14: =SUM(G8:G13) -> 0 | I14: =IF((G14-C14+J14)<0,TEXT(C14-G14-J14,"-[h]:mm"),G14-C14+J14) -> 0 | J14: =SUM(J8:J13) -> 0 | K14: =IF(LEFT(I4,1)="-",IF((G14-C14+J14-K6)<0,TEXT(C14-G14-J14+K6,"-[hh]:mm"),G14-C14+J14-K6),IF((G14-C14+J14+K6)<0,TEXT(C14-G14+J14-K6,"-[hh]:mm"),G14-C14+J14+K6)) -> 0 | L14: =SUM(L8:L13) -> 0 | M14: =SUM(M8:M13) -> 0 | N14: =IF((M14-L14)<0,TEXT(L14-M14,"-[h]:mm"),M14-L14) -> 0
B15: Mo | G15: =IF(OR(ISBLANK(D15),ISBLANK(E15)),0,E15-D15-F15) -> 0 | I15: =IF((G15-C15)<0,TEXT(C15-G15,"-[h]:mm"),G15-C15) -> 0 | N15: =IF((M15-L15)<0,TEXT(L15-M15,"-[h]:mm"),M15-L15) -> 0
A16: =A19+4 -> 39 | B16: Di | G16: =IF(OR(ISBLANK(D16),ISBLANK(E16)),0,E16-D16-F16) -> 0 | I16: =IF((G16-C16)<0,TEXT(C16-G16,"-[h]:mm"),G16-C16) -> 0 | N16: =IF((M16-L16)<0,TEXT(L16-M16,"-[h]:mm"),M16-L16) -> 0
B17: Mi | G17: =IF(OR(ISBLANK(D17),ISBLANK(E17)),0,E17-D17-F17) -> 0 | I17: =IF((G17-C17)<0,TEXT(C17-G17,"-[h]:mm"),G17-C17) -> 0 | N17: =IF((M17-L17)<0,TEXT(L17-M17,"-[h]:mm"),M17-L17) -> 0
A18: - | B18: Do | G18: =IF(OR(ISBLANK(D18),ISBLANK(E18)),0,E18-D18-F18) -> 0 | I18: =IF((G18-C18)<0,TEXT(C18-G18,"-[h]:mm"),G18-C18) -> 0 | N18: =IF((M18-L18)<0,TEXT(L18-M18,"-[h]:mm"),M18-L18) -> 0
A19: =A9+3 -> 35 | B19: Fr | G19: =IF(OR(ISBLANK(D19),ISBLANK(E19)),0,E19-D19-F19) -> 0 | I19: =IF((G19-C19)<0,TEXT(C19-G19,"-[h]:mm"),G19-C19) -> 0 | N19: =IF((M19-L19)<0,TEXT(L19-M19,"-[h]:mm"),M19-L19) -> 0
B20: Sonst | G20: =E20-D20-F20 -> 0 | I20: =IF((G20-C20)<0,TEXT(C20-G20,"-[h]:mm"),G20-C20) -> 0 | N20: =IF((M20-L20)<0,TEXT(L20-M20,"-[h]:mm"),M20-L20) -> 0
A21: =IF(A14<>"",A14+1,"") -> 6 | B21: ∑ | C21: =SUM(C15:C20) -> 0 | F21: =SUM(F15:F20) -> 0 | G21: =SUM(G15:G20) -> 0 | I21: =IF((G21-C21+J21)<0,TEXT(C21-G21-J21,"-[h]:mm"),G21-C21+J21) -> 0 | J21: =SUM(J15:J20) -> 0 | K21: =IF(LEFT(K14,1)="-",IF((G21-C21+J21-L6)<0,TEXT(C21-G21-J21+L6,"-[hh]:mm"),G21-C21+J21-L6),IF((G21-C21+J21+L6)<0,TEXT(C21-G21+J21-L6,"-[hh]:mm"),G21-C21+J21+L6)) -> 0 | L21: =SUM(L15:L20) -> 0 | M21: =SUM(M15:M20) -> 0 | N21: =IF((M21-L21)<0,TEXT(L21-M21,"-[h]:mm"),M21-L21) -> 0
B22: Mo | G22: =IF(OR(ISBLANK(D22),ISBLANK(E22)),0,E22-D22-F22) -> 0 | I22: =IF((G22-C22)<0,TEXT(C22-G22,"-[h]:mm"),G22-C22) -> 0 | N22: =IF((M22-L22)<0,TEXT(L22-M22,"-[h]:mm"),M22-L22) -> 0
A23: =A26+4 -> 46 | B23: Di | G23: =IF(OR(ISBLANK(D23),ISBLANK(E23)),0,E23-D23-F23) -> 0 | I23: =IF((G23-C23)<0,TEXT(C23-G23,"-[h]:mm"),G23-C23) -> 0 | N23: =IF((M23-L23)<0,TEXT(L23-M23,"-[h]:mm"),M23-L23) -> 0
B24: Mi | G24: =IF(OR(ISBLANK(D24),ISBLANK(E24)),0,E24-D24-F24) -> 0 | I24: =IF((G24-C24)<0,TEXT(C24-G24,"-[h]:mm"),G24-C24) -> 0 | N24: =IF((M24-L24)<0,TEXT(L24-M24,"-[h]:mm"),M24-L24) -> 0
A25: - | B25: Do | G25: =IF(OR(ISBLANK(D25),ISBLANK(E25)),0,E25-D25-F25) -> 0 | I25: =IF((G25-C25)<0,TEXT(C25-G25,"-[h]:mm"),G25-C25) -> 0 | N25: =IF((M25-L25)<0,TEXT(L25-M25,"-[h]:mm"),M25-L25) -> 0
A26: =A16+3 -> 42 | B26: Fr | G26: =IF(OR(ISBLANK(D26),ISBLANK(E26)),0,E26-D26-F26) -> 0 | I26: =IF((G26-C26)<0,TEXT(C26-G26,"-[h]:mm"),G26-C26) -> 0 | N26: =IF((M26-L26)<0,TEXT(L26-M26,"-[h]:mm"),M26-L26) -> 0
B27: Sonst | G27: =IF(OR(ISBLANK(D27),ISBLANK(E27)),0,E27-D27-F27) -> 0 | I27: =IF((G27-C27)<0,TEXT(C27-G27,"-[h]:mm"),G27-C27) -> 0 | N27: =IF((M27-L27)<0,TEXT(L27-M27,"-[h]:mm"),M27-L27) -> 0
A28: =IF(A21<>"",A21+1,"") -> 7 | B28: ∑ | C28: =SUM(C22:C27) -> 0 | F28: =SUM(F22:F27) -> 0 | G28: =SUM(G22:G27) -> 0 | I28: =IF((G28-C28+J28)<0,TEXT(C28-G28-J28,"-[h]:mm"),G28-C28+J28) -> 0 | J28: =SUM(J22:J27) -> 0 | K28: =IF(LEFT(K21,1)="-",IF((G28-C28+J28-M6)<0,TEXT(C28-G28-J28+M6,"-[hh]:mm"),G28-C28+J28-M6),IF((G28-C28+J28+M6)<0,TEXT(C28-G28+J28-M6,"-[hh]:mm"),G28-C28+J28+M6)) -> 0 | L28: =SUM(L22:L27) -> 0 | M28: =SUM(M22:M27) -> 0 | N28: =IF((M28-L28)<0,TEXT(L28-M28,"-[h]:mm"),M28-L28) -> 0
B29: Mo | G29: =IF(OR(ISBLANK(D29),ISBLANK(E29)),0,E29-D29-F29) -> 0 | I29: =IF((G29-C29)<0,TEXT(C29-G29,"-[h]:mm"),G29-C29) -> 0 | N29: =IF((M29-L29)<0,TEXT(L29-M29,"-[h]:mm"),M29-L29) -> 0
A30: =A33+4 -> 53 | B30: Di | G30: =IF(OR(ISBLANK(D30),ISBLANK(E30)),0,E30-D30-F30) -> 0 | I30: =IF((G30-C30)<0,TEXT(C30-G30,"-[h]:mm"),G30-C30) -> 0 | N30: =IF((M30-L30)<0,TEXT(L30-M30,"-[h]:mm"),M30-L30) -> 0
B31: Mi | G31: =IF(OR(ISBLANK(D31),ISBLANK(E31)),0,E31-D31-F31) -> 0 | I31: =IF((G31-C31)<0,TEXT(C31-G31,"-[h]:mm"),G31-C31) -> 0 | N31: =IF((M31-L31)<0,TEXT(L31-M31,"-[h]:mm"),M31-L31) -> 0
A32: - | B32: Do | G32: =IF(OR(ISBLANK(D32),ISBLANK(E32)),0,E32-D32-F32) -> 0 | I32: =IF((G32-C32)<0,TEXT(C32-G32,"-[h]:mm"),G32-C32) -> 0 | N32: =IF((M32-L32)<0,TEXT(L32-M32,"-[h]:mm"),M32-L32) -> 0
A33: =A23+3 -> 49 | B33: Fr | G33: =IF(OR(ISBLANK(D33),ISBLANK(E33)),0,E33-D33-F33) -> 0 | I33: =IF((G33-C33)<0,TEXT(C33-G33,"-[hh]:mm"),G33-C33) -> 0 | N33: =IF((M33-L33)<0,TEXT(L33-M33,"-[h]:mm"),M33-L33) -> 0
B34: Sonst | G34: =IF(OR(ISBLANK(D34),ISBLANK(E34)),0,E34-D34-F34) -> 0 | I34: =IF((G34-C34)<0,TEXT(C34-G34,"-[hh]:mm"),G34-C34) -> 0 | N34: =IF((M34-L34)<0,TEXT(L34-M34,"-[h]:mm"),M34-L34) -> 0
A35: =IF(A28<>"",A28+1,"") -> 8 | B35: ∑ | C35: =SUM(C29:C34) -> 0 | F35: =SUM(F29:F34) -> 0 | G35: =SUM(G29:G34) -> 0 | I35: =IF((G35-C35+J35)<0,TEXT(C35-G35-J35,"-[h]:mm"),G35-C35+J35) -> 0 | J35: =SUM(J29:J34) -> 0 | K35: =IF(LEFT(K28,1)="-",IF((G35-C35+J35-N6)<0,TEXT(C35-G35-J35+N6,"-[hh]:mm"),G35-C35+J35-N6),IF((G35-C35+J35+N6)<0,TEXT(C35-G35+J35-N6,"-[hh]:mm"),G35-C35+J35+N6)) -> 0 | L35: =SUM(L29:L34) -> 0 | M35: =SUM(M29:M34) -> 0 | N35: =IF((M35-L35)<0,TEXT(L35-M35,"-[h]:mm"),M35-L35) -> 0
B36: ∑ | C36: =C14+C21+C28+C35 -> 0 | G36: =G14+G21+G28+G35 -> 0 | I36: =IF((G36-C36+J36)<0,TEXT(C36-G36-J36,"-[h]:mm"),G36-C36+J36) -> 0 | J36: =J14+J21+J28+J35 -> 0 | K36: =K35 -> 0 | N36: Gesamtstunden = Übertrag auf neues Blatt | Q36: =K36 -> 0
N37: Mehrarbeit in der vierten Woche = Übertrag auf neues Blatt | Q37: =I35 -> 0
A38: U | F38: =TODAY() -> 46019
A39: K | F39: Datum | M39: Unterschrift Mitarbeiter/-in
A40: F
...

Sheet KW 09-12
A1: Arbeitszeiterfassung (Freizeitausgleich) (Dieser Vordruck ist zu verwenden, wenn auf der Erklärung die Option "Freizeitausgleich" angekreuzt wurde)
A2: Name: | C2: =Stammangaben!$B$3 -> 0 | N2: TE | O2: =Stammangaben!B4 -> 0
A3: =IF(NOT(Stammangaben!C7=""),Stammangaben!C7,Stammangaben!C6) -> 0 | B3: Std / Woche | C3: gesamte Arbeitszeit | L3: VZ-Zeiten
C4: Übertrag der Gesamtstunden aus letztem Blatt | I4: ='KW 05-08'!K36 -> 0
C5: Übertrag der Mehrarbeit aus vierter Woche vom letzten Blatt | I5: ='KW 05-08'!I35 -> 0
K6: =IF(LEFT(I4,1)="-",RIGHT(I4,LEN(I4)-1),I4) -> 0 | L6: =IF(LEFT(K14,1)="-",RIGHT(K14,LEN(K14)-1),K14) -> 0 | M6: =IF(LEFT(K21,1)="-",RIGHT(K21,LEN(K21)-1),K21) -> 0 | N6: =IF(LEFT(K28,1)="-",RIGHT(K28,LEN(K28)-1),K28) -> 0
A7: KW | C7: Soll | D7: von | E7: bis | F7: Pause | G7: Ist | H7: U/K/F/AB | I7: Haben/ Woche | J7: AZ aus Bereit-schaft | K7: Haben ges. | L7: Soll | M7: Ist | N7: Haben | O7: außer Haus | P7: Begründung für Abweichung Soll / Ist bei VZ | Q7: bei relevanter Abweichung von der Soll-Arbeitszeit (= mehr als 30 min.) Begründung
B8: Mo | G8: =IF(OR(ISBLANK(D8),ISBLANK(E8)),0,E8-D8-F8) -> 0 | I8: =IF((G8-C8)<0,TEXT(C8-G8,"-[h]:mm"),G8-C8) -> 0 | N8: =IF((M8-L8)<0,TEXT(L8-M8,"-[h]:mm"),M8-L8) -> 0
A9: =A12+4 -> 60 | B9: Di | G9: =IF(OR(ISBLANK(D9),ISBLANK(E9)),0,E9-D9-F9) -> 0 | I9: =IF((G9-C9)<0,TEXT(C9-G9,"-[h]:mm"),G9-C9) -> 0 | N9: =IF((M9-L9)<0,TEXT(L9-M9,"-[h]:mm"),M9-L9) -> 0
B10: Mi | G10: =IF(OR(ISBLANK(D10),ISBLANK(E10)),0,E10-D10-F10) -> 0 | I10: =IF((G10-C10)<0,TEXT(C10-G10,"-[h]:mm"),G10-C10) -> 0 | N10: =IF((M10-L10)<0,TEXT(L10-M10,"-[h]:mm"),M10-L10) -> 0
A11: - | B11: Do | G11: =IF(OR(ISBLANK(D11),ISBLANK(E11)),0,E11-D11-F11) -> 0 | I11: =IF((G11-C11)<0,TEXT(C11-G11,"-[h]:mm"),G11-C11) -> 0 | N11: =IF((M11-L11)<0,TEXT(L11-M11,"-[h]:mm"),M11-L11) -> 0
A12: ='KW 05-08'!A30+3 -> 56 | B12: Fr | G12: =IF(OR(ISBLANK(D12),ISBLANK(E12)),0,E12-D12-F12) -> 0 | I12: =IF((G12-C12)<0,TEXT(C12-G12,"-[h]:mm"),G12-C12) -> 0 | N12: =IF((M12-L12)<0,TEXT(L12-M12,"-[h]:mm"),M12-L12) -> 0
B13: Sonst | G13: =IF(OR(ISBLANK(D13),ISBLANK(E13)),0,E13-D13-F13) -> 0 | I13: =IF((G13-C13)<0,TEXT(C13-G13,"-[h]:mm"),G13-C13) -> 0 | N13: =IF((M13-L13)<0,TEXT(L13-M13,"-[h]:mm"),M13-L13) -> 0
A14: ='KW 05-08'!A35+1 -> 9 | B14: ∑ | C14: =SUM(C8:C13) -> 0 | F14: =SUM(F8:F13) -> 0 | G14: =SUM(G8:G13) -> 0 | I14: =IF((G14-C14+J14)<0,TEXT(C14-G14-J14,"-[h]:mm"),G14-C14+J14) -> 0 | J14: =SUM(J8:J13) -> 0 | K14: =IF(LEFT(I4,1)="-",IF((G14-C14+J14-K6)<0,TEXT(C14-G14-J14+K6,"-[hh]:mm"),G14-C14+J14-K6),IF((G14-C14+J14+K6)<0,TEXT(C14-G14+J14-K6,"-[hh]:mm"),G14-C14+J14+K6)) -> 0 | L14: =SUM(L8:L13) -> 0 | M14: =SUM(M8:M13) -> 0 | N14: =IF((M14-L14)<0,TEXT(L14-M14,"-[h]:mm"),M14-L14) -> 0
B15: Mo | G15: =IF(OR(ISBLANK(D15),ISBLANK(E15)),0,E15-D15-F15) -> 0 | I15: =IF((G15-C15)<0,TEXT(C15-G15,"-[h]:mm"),G15-C15) -> 0 | N15: =IF((M15-L15)<0,TEXT(L15-M15,"-[h]:mm"),M15-L15) -> 0
A16: =A19+4 -> 67 | B16: Di | G16: =IF(OR(ISBLANK(D16),ISBLANK(E16)),0,E16-D16-F16) -> 0 | I16: =IF((G16-C16)<0,TEXT(C16-G16,"-[h]:mm"),G16-C16) -> 0 | N16: =IF((M16-L16)<0,TEXT(L16-M16,"-[h]:mm"),M16-L16) -> 0
B17: Mi | G17: =IF(OR(ISBLANK(D17),ISBLANK(E17)),0,E17-D17-F17) -> 0 | I17: =IF((G17-C17)<0,TEXT(C17-G17,"-[h]:mm"),G17-C17) -> 0 | N17: =IF((M17-L17)<0,TEXT(L17-M17,"-[h]:mm"),M17-L17) -> 0
A18: - | B18: Do | G18: =IF(OR(ISBLANK(D18),ISBLANK(E18)),0,E18-D18-F18) -> 0 | I18: =IF((G18-C18)<0,TEXT(C18-G18,"-[h]:mm"),G18-C18) -> 0 | N18: =IF((M18-L18)<0,TEXT(L18-M18,"-[h]:mm"),M18-L18) -> 0
A19: =A9+3 -> 63 | B19: Fr | G19: =IF(OR(ISBLANK(D19),ISBLANK(E19)),0,E19-D19-F19) -> 0 | I19: =IF((G19-C19)<0,TEXT(C19-G19,"-[h]:mm"),G19-C19) -> 0 | N19: =IF((M19-L19)<0,TEXT(L19-M19,"-[h]:mm"),M19-L19) -> 0
B20: Sonst | G20: =E20-D20-F20 -> 0 | I20: =IF((G20-C20)<0,TEXT(C20-G20,"-[h]:mm"),G20-C20) -> 0 | N20: =IF((M20-L20)<0,TEXT(L20-M20,"-[h]:mm"),M20-L20) -> 0
A21: =IF(A14<>"",A14+1,"") -> 10 | B21: ∑ | C21: =SUM(C15:C20) -> 0 | F21: =SUM(F15:F20) -> 0 | G21: =SUM(G15:G20) -> 0 | I21: =IF((G21-C21+J21)<0,TEXT(C21-G21-J21,"-[h]:mm"),G21-C21+J21) -> 0 | J21: =SUM(J15:J20) -> 0 | K21: =IF(LEFT(K14,1)="-",IF((G21-C21+J21-L6)<0,TEXT(C21-G21-J21+L6,"-[hh]:mm"),G21-C21+J21-L6),IF((G21-C21+J21+L6)<0,TEXT(C21-G21+J21-L6,"-[hh]:mm"),G21-C21+J21+L6)) -> 0 | L21: =SUM(L15:L20) -> 0 | M21: =SUM(M15:M20) -> 0 | N21: =IF((M21-L21)<0,TEXT(L21-M21,"-[h]:mm"),M21-L21) -> 0
B22: Mo | G22: =IF(OR(ISBLANK(D22),ISBLANK(E22)),0,E22-D22-F22) -> 0 | I22: =IF((G22-C22)<0,TEXT(C22-G22,"-[h]:mm"),G22-C22) -> 0 | N22: =IF((M22-L22)<0,TEXT(L22-M22,"-[h]:mm"),M22-L22) -> 0
A23: =A26+4 -> 74 | B23: Di | G23: =IF(OR(ISBLANK(D23),ISBLANK(E23)),0,E23-D23-F23) -> 0 | I23: =IF((G23-C23)<0,TEXT(C23-G23,"-[h]:mm"),G23-C23) -> 0 | N23: =IF((M23-L23)<0,TEXT(L23-M23,"-[h]:mm"),M23-L23) -> 0
B24: Mi | G24: =IF(OR(ISBLANK(D24),ISBLANK(E24)),0,E24-D24-F24) -> 0 | I24: =IF((G24-C24)<0,TEXT(C24-G24,"-[h]:mm"),G24-C24) -> 0 | N24: =IF((M24-L24)<0,TEXT(L24-M24,"-[h]:mm"),M24-L24) -> 0
A25: - | B25: Do | G25: =IF(OR(ISBLANK(D25),ISBLANK(E25)),0,E25-D25-F25) -> 0 | I25: =IF((G25-C25)<0,TEXT(C25-G25,"-[h]:mm"),G25-C25) -> 0 | N25: =IF((M25-L25)<0,TEXT(L25-M25,"-[h]:mm"),M25-L25) -> 0
A26: =A16+3 -> 70 | B26: Fr | G26: =IF(OR(ISBLANK(D26),ISBLANK(E26)),0,E26-D26-F26) -> 0 | I26: =IF((G26-C26)<0,TEXT(C26-G26,"-[h]:mm"),G26-C26) -> 0 | N26: =IF((M26-L26)<0,TEXT(L26-M26,"-[h]:mm"),M26-L26) -> 0
B27: Sonst | G27: =IF(OR(ISBLANK(D27),ISBLANK(E27)),0,E27-D27-F27) -> 0 | I27: =IF((G27-C27)<0,TEXT(C27-G27,"-[h]:mm"),G27-C27) -> 0 | N27: =IF((M27-L27)<0,TEXT(L27-M27,"-[h]:mm"),M27-L27) -> 0
A28: =IF(A21<>"",A21+1,"") -> 11 | B28: ∑ | C28: =SUM(C22:C27) -> 0 | F28: =SUM(F22:F27) -> 0 | G28: =SUM(G22:G27) -> 0 | I28: =IF((G28-C28+J28)<0,TEXT(C28-G28-J28,"-[h]:mm"),G28-C28+J28) -> 0 | J28: =SUM(J22:J27) -> 0 | K28: =IF(LEFT(K21,1)="-",IF((G28-C28+J28-M6)<0,TEXT(C28-G28-J28+M6,"-[hh]:mm"),G28-C28+J28-M6),IF((G28-C28+J28+M6)<0,TEXT(C28-G28+J28-M6,"-[hh]:mm"),G28-C28+J28+M6)) -> 0 | L28: =SUM(L22:L27) -> 0 | M28: =SUM(M22:M27) -> 0 | N28: =IF((M28-L28)<0,TEXT(L28-M28,"-[h]:mm"),M28-L28) -> 0
B29: Mo | G29: =IF(OR(ISBLANK(D29),ISBLANK(E29)),0,E29-D29-F29) -> 0 | I29: =IF((G29-C29)<0,TEXT(C29-G29,"-[h]:mm"),G29-C29) -> 0 | N29: =IF((M29-L29)<0,TEXT(L29-M29,"-[h]:mm"),M29-L29) -> 0
A30: =A33+4 -> 81 | B30: Di | G30: =IF(OR(ISBLANK(D30),ISBLANK(E30)),0,E30-D30-F30) -> 0 | I30: =IF((G30-C30)<0,TEXT(C30-G30,"-[h]:mm"),G30-C30) -> 0 | N30: =IF((M30-L30)<0,TEXT(L30-M30,"-[h]:mm"),M30-L30) -> 0
B31: Mi | G31: =IF(OR(ISBLANK(D31),ISBLANK(E31)),0,E31-D31-F31) -> 0 | I31: =IF((G31-C31)<0,TEXT(C31-G31,"-[h]:mm"),G31-C31) -> 0 | N31: =IF((M31-L31)<0,TEXT(L31-M31,"-[h]:mm"),M31-L31) -> 0
A32: - | B32: Do | G32: =IF(OR(ISBLANK(D32),ISBLANK(E32)),0,E32-D32-F32) -> 0 | I32: =IF((G32-C32)<0,TEXT(C32-G32,"-[h]:mm"),G32-C32) -> 0 | N32: =IF((M32-L32)<0,TEXT(L32-M32,"-[h]:mm"),M32-L32) -> 0
A33: =A23+3 -> 77 | B33: Fr | G33: =IF(OR(ISBLANK(D33),ISBLANK(E33)),0,E33-D33-F33) -> 0 | I33: =IF((G33-C33)<0,TEXT(C33-G33,"-[hh]:mm"),G33-C33) -> 0 | N33: =IF((M33-L33)<0,TEXT(L33-M33,"-[h]:mm"),M33-L33) -> 0
B34: Sonst | G34: =IF(OR(ISBLANK(D34),ISBLANK(E34)),0,E34-D34-F34) -> 0 | I34: =IF((G34-C34)<0,TEXT(C34-G34,"-[hh]:mm"),G34-C34) -> 0 | N34: =IF((M34-L34)<0,TEXT(L34-M34,"-[h]:mm"),M34-L34) -> 0
A35: =IF(A28<>"",A28+1,"") -> 12 | B35: ∑ | C35: =SUM(C29:C34) -> 0 | F35: =SUM(F29:F34) -> 0 | G35: =SUM(G29:G34) -> 0 | I35: =IF((G35-C35+J35)<0,TEXT(C35-G35-J35,"-[h]:mm"),G35-C35+J35) -> 0 | J35: =SUM(J29:J34) -> 0 | K35: =IF(LEFT(K28,1)="-",IF((G35-C35+J35-N6)<0,TEXT(C35-G35-J35+N6,"-[hh]:mm"),G35-C35+J35-N6),IF((G35-C35+J35+N6)<0,TEXT(C35-G35+J35-N6,"-[hh]:mm"),G35-C35+J35+N6)) -> 0 | L35: =SUM(L29:L34) -> 0 | M35: =SUM(M29:M34) -> 0 | N35: =IF((M35-L35)<0,TEXT(L35-M35,"-[h]:mm"),M35-L35) -> 0
B36: ∑ | C36: =C14+C21+C28+C35 -> 0 | G36: =G14+G21+G28+G35 -> 0 | I36: =IF((G36-C36+J36)<0,TEXT(C36-G36-J36,"-[h]:mm"),G36-C36+J36) -> 0 | J36: =J14+J21+J28+J35 -> 0 | K36: =K35 -> 0 | N36: Gesamtstunden = Übertrag auf neues Blatt | Q36: =K36 -> 0
N37: Mehrarbeit in der vierten Woche = Übertrag auf neues Blatt | Q37: =I35 -> 0
A38: U | F38: =TODAY() -> 46019
A39: K | F39: Datum | M39: Unterschrift Mitarbeiter/-in
A40: F
...

Sheet KW 13-16
A1: Arbeitszeiterfassung (Freizeitausgleich) (Dieser Vordruck ist zu verwenden, wenn auf der Erklärung die Option "Freizeitausgleich" angekreuzt wurde)
A2: Name: | C2: =Stammangaben!$B$3 -> 0 | N2: TE | O2: =Stammangaben!B4 -> 0
A3: =IF(NOT(Stammangaben!C7=""),Stammangaben!C7,Stammangaben!C6) -> 0 | B3: Std / Woche | C3: gesamte Arbeitszeit | L3: VZ-Zeiten
C4: Übertrag der Gesamtstunden aus letztem Blatt | I4: ='KW 09-12'!K36 -> 0
C5: Übertrag der Mehrarbeit aus vierter Woche vom letzten Blatt | I5: ='KW 09-12'!I35 -> 0
K6: =IF(LEFT(I4,1)="-",RIGHT(I4,LEN(I4)-1),I4) -> 0 | L6: =IF(LEFT(K14,1)="-",RIGHT(K14,LEN(K14)-1),K14) -> 0 | M6: =IF(LEFT(K21,1)="-",RIGHT(K21,LEN(K21)-1),K21) -> 0 | N6: =IF(LEFT(K28,1)="-",RIGHT(K28,LEN(K28)-1),K28) -> 0
A7: KW | C7: Soll | D7: von | E7: bis | F7: Pause | G7: Ist | H7: U/K/F/AB | I7: Haben/ Woche | J7: AZ aus Bereit-schaft | K7: Haben ges. | L7: Soll | M7: Ist | N7: Haben | O7: außer Haus | P7: Begründung für Abweichung Soll / Ist bei VZ | Q7: bei relevanter Abweichung von der Soll-Arbeitszeit (= mehr als 30 min.) Begründung
B8: Mo | G8: =IF(OR(ISBLANK(D8),ISBLANK(E8)),0,E8-D8-F8) -> 0 | I8: =IF((G8-C8)<0,TEXT(C8-G8,"-[h]:mm"),G8-C8) -> 0 | N8: =IF((M8-L8)<0,TEXT(L8-M8,"-[h]:mm"),M8-L8) -> 0
A9: =A12+4 -> 88 | B9: Di | G9: =IF(OR(ISBLANK(D9),ISBLANK(E9)),0,E9-D9-F9) -> 0 | I9: =IF((G9-C9)<0,TEXT(C9-G9,"-[h]:mm"),G9-C9) -> 0 | N9: =IF((M9-L9)<0,TEXT(L9-M9,"-[h]:mm"),M9-L9) -> 0
B10: Mi | G10: =IF(OR(ISBLANK(D10),ISBLANK(E10)),0,E10-D10-F10) -> 0 | I10: =IF((G10-C10)<0,TEXT(C10-G10,"-[h]:mm"),G10-C10) -> 0 | N10: =IF((M10-L10)<0,TEXT(L10-M10,"-[h]:mm"),M10-L10) -> 0
A11: - | B11: Do | G11: =IF(OR(ISBLANK(D11),ISBLANK(E11)),0,E11-D11-F11) -> 0 | I11: =IF((G11-C11)<0,TEXT(C11-G11,"-[h]:mm"),G11-C11) -> 0 | N11: =IF((M11-L11)<0,TEXT(L11-M11,"-[h]:mm"),M11-L11) -> 0
A12: ='KW 09-12'!A30+3 -> 84 | B12: Fr | G12: =IF(OR(ISBLANK(D12),ISBLANK(E12)),0,E12-D12-F12) -> 0 | I12: =IF((G12-C12)<0,TEXT(C12-G12,"-[h]:mm"),G12-C12) -> 0 | N12: =IF((M12-L12)<0,TEXT(L12-M12,"-[h]:mm"),M12-L12) -> 0
B13: Sonst | G13: =IF(OR(ISBLANK(D13),ISBLANK(E13)),0,E13-D13-F13) -> 0 | I13: =IF((G13-C13)<0,TEXT(C13-G13,"-[h]:mm"),G13-C13) -> 0 | N13: =IF((M13-L13)<0,TEXT(L13-M13,"-[h]:mm"),M13-L13) -> 0
A14: ='KW 09-12'!A35+1 -> 13 | B14: ∑ | C14: =SUM(C8:C13) -> 0 | F14: =SUM(F8:F13) -> 0 | G14: =SUM(G8:G13) -> 0 | I14: =IF((G14-C14+J14)<0,TEXT(C14-G14-J14,"-[h]:mm"),G14-C14+J14) -> 0 | J14: =SUM(J8:J13) -> 0 | K14: =IF(LEFT(I4,1)="-",IF((G14-C14+J14-K6)<0,TEXT(C14-G14-J14+K6,"-[hh]:mm"),G14-C14+J14-K6),IF((G14-C14+J14+K6)<0,TEXT(C14-G14+J14-K6,"-[hh]:mm"),G14-C14+J14+K6)) -> 0 | L14: =SUM(L8:L13) -> 0 | M14: =SUM(M8:M13) -> 0 | N14: =IF((M14-L14)<0,TEXT(L14-M14,"-[h]:mm"),M14-L14) -> 0
B15: Mo | G15: =IF(OR(ISBLANK(D15),ISBLANK(E15)),0,E15-D15-F15) -> 0 | I15: =IF((G15-C15)<0,TEXT(C15-G15,"-[h]:mm"),G15-C15) -> 0 | N15: =IF((M15-L15)<0,TEXT(L15-M15,"-[h]:mm"),M15-L15) -> 0
A16: =A19+4 -> 95 | B16: Di | G16: =IF(OR(ISBLANK(D16),ISBLANK(E16)),0,E16-D16-F16) -> 0 | I16: =IF((G16-C16)<0,TEXT(C16-G16,"-[h]:mm"),G16-C16) -> 0 | N16: =IF((M16-L16)<0,TEXT(L16-M16,"-[h]:mm"),M16-L16) -> 0
B17: Mi | G17: =IF(OR(ISBLANK(D17),ISBLANK(E17)),0,E17-D17-F17) -> 0 | I17: =IF((G17-C17)<0,TEXT(C17-G17,"-[h]:mm"),G17-C17) -> 0 | N17: =IF((M17-L17)<0,TEXT(L17-M17,"-[h]:mm"),M17-L17) -> 0
A18: - | B18: Do | G18: =IF(OR(ISBLANK(D18),ISBLANK(E18)),0,E18-D18-F18) -> 0 | I18: =IF((G18-C18)<0,TEXT(C18-G18,"-[h]:mm"),G18-C18) -> 0 | N18: =IF((M18-L18)<0,TEXT(L18-M18,"-[h]:mm"),M18-L18) -> 0
A19: =A9+3 -> 91 | B19: Fr | G19: =IF(OR(ISBLANK(D19),ISBLANK(E19)),0,E19-D19-F19) -> 0 | I19: =IF((G19-C19)<0,TEXT(C19-G19,"-[h]:mm"),G19-C19) -> 0 | N19: =IF((M19-L19)<0,TEXT(L19-M19,"-[h]:mm"),M19-L19) -> 0
B20: Sonst | G20: =E20-D20-F20 -> 0 | I20: =IF((G20-C20)<0,TEXT(C20-G20,"-[h]:mm"),G20-C20) -> 0 | N20: =IF((M20-L20)<0,TEXT(L20-M20,"-[h]:mm"),M20-L20) -> 0
A21: =IF(A14<>"",A14+1,"") -> 14 | B21: ∑ | C21: =SUM(C15:C20) -> 0 | F21: =SUM(F15:F20) -> 0 | G21: =SUM(G15:G20) -> 0 | I21: =IF((G21-C21+J21)<0,TEXT(C21-G21-J21,"-[h]:mm"),G21-C21+J21) -> 0 | J21: =SUM(J15:J20) -> 0 | K21: =IF(LEFT(K14,1)="-",IF((G21-C21+J21-L6)<0,TEXT(C21-G21-J21+L6,"-[hh]:mm"),G21-C21+J21-L6),IF((G21-C21+J21+L6)<0,TEXT(C21-G21+J21-L6,"-[hh]:mm"),G21-C21+J21+L6)) -> 0 | L21: =SUM(L15:L20) -> 0 | M21: =SUM(M15:M20) -> 0 | N21: =IF((M21-L21)<0,TEXT(L21-M21,"-[h]:mm"),M21-L21) -> 0
B22: Mo | G22: =IF(OR(ISBLANK(D22),ISBLANK(E22)),0,E22-D22-F22) -> 0 | I22: =IF((G22-C22)<0,TEXT(C22-G22,"-[h]:mm"),G22-C22) -> 0 | N22: =IF((M22-L22)<0,TEXT(L22-M22,"-[h]:mm"),M22-L22) -> 0
A23: =A26+4 -> 102 | B23: Di | G23: =IF(OR(ISBLANK(D23),ISBLANK(E23)),0,E23-D23-F23) -> 0 | I23: =IF((G23-C23)<0,TEXT(C23-G23,"-[h]:mm"),G23-C23) -> 0 | N23: =IF((M23-L23)<0,TEXT(L23-M23,"-[h]:mm"),M23-L23) -> 0
B24: Mi | G24: =IF(OR(ISBLANK(D24),ISBLANK(E24)),0,E24-D24-F24) -> 0 | I24: =IF((G24-C24)<0,TEXT(C24-G24,"-[h]:mm"),G24-C24) -> 0 | N24: =IF((M24-L24)<0,TEXT(L24-M24,"-[h]:mm"),M24-L24) -> 0
A25: - | B25: Do | G25: =IF(OR(ISBLANK(D25),ISBLANK(E25)),0,E25-D25-F25) -> 0 | I25: =IF((G25-C25)<0,TEXT(C25-G25,"-[h]:mm"),G25-C25) -> 0 | N25: =IF((M25-L25)<0,TEXT(L25-M25,"-[h]:mm"),M25-L25) -> 0
A26: =A16+3 -> 98 | B26: Fr | G26: =IF(OR(ISBLANK(D26),ISBLANK(E26)),0,E26-D26-F26) -> 0 | I26: =IF((G26-C26)<0,TEXT(C26-G26,"-[h]:mm"),G26-C26) -> 0 | N26: =IF((M26-L26)<0,TEXT(L26-M26,"-[h]:mm"),M26-L26) -> 0
B27: Sonst | G27: =IF(OR(ISBLANK(D27),ISBLANK(E27)),0,E27-D27-F27) -> 0 | I27: =IF((G27-C27)<0,TEXT(C27-G27,"-[h]:mm"),G27-C27) -> 0 | N27: =IF((M27-L27)<0,TEXT(L27-M27,"-[h]:mm"),M27-L27) -> 0
A28: =IF(A21<>"",A21+1,"") -> 15 | B28: ∑ | C28: =SUM(C22:C27) -> 0 | F28: =SUM(F22:F27) -> 0 | G28: =SUM(G22:G27) -> 0 | I28: =IF((G28-C28+J28)<0,TEXT(C28-G28-J28,"-[h]:mm"),G28-C28+J28) -> 0 | J28: =SUM(J22:J27) -> 0 | K28: =IF(LEFT(K21,1)="-",IF((G28-C28+J28-M6)<0,TEXT(C28-G28-J28+M6,"-[hh]:mm"),G28-C28+J28-M6),IF((G28-C28+J28+M6)<0,TEXT(C28-G28+J28-M6,"-[hh]:mm"),G28-C28+J28+M6)) -> 0 | L28: =SUM(L22:L27) -> 0 | M28: =SUM(M22:M27) -> 0 | N28: =IF((M28-L28)<0,TEXT(L28-M28,"-[h]:mm"),M28-L28) -> 0
B29: Mo | G29: =IF(OR(ISBLANK(D29),ISBLANK(E29)),0,E29-D29-F29) -> 0 | I29: =IF((G29-C29)<0,TEXT(C29-G29,"-[h]:mm"),G29-C29) -> 0 | N29: =IF((M29-L29)<0,TEXT(L29-M29,"-[h]:mm"),M29-L29) -> 0
A30: =A33+4 -> 109 | B30: Di | G30: =IF(OR(ISBLANK(D30),ISBLANK(E30)),0,E30-D30-F30) -> 0 | I30: =IF((G30-C30)<0,TEXT(C30-G30,"-[h]:mm"),G30-C30) -> 0 | N30: =IF((M30-L30)<0,TEXT(L30-M30,"-[h]:mm"),M30-L30) -> 0
B31: Mi | G31: =IF(OR(ISBLANK(D31),ISBLANK(E31)),0,E31-D31-F31) -> 0 | I31: =IF((G31-C31)<0,TEXT(C31-G31,"-[h]:mm"),G31-C31) -> 0 | N31: =IF((M31-L31)<0,TEXT(L31-M31,"-[h]:mm"),M31-L31) -> 0
A32: - | B32: Do | G32: =IF(OR(ISBLANK(D32),ISBLANK(E32)),0,E32-D32-F32) -> 0 | I32: =IF((G32-C32)<0,TEXT(C32-G32,"-[h]:mm"),G32-C32) -> 0 | N32: =IF((M32-L32)<0,TEXT(L32-M32,"-[h]:mm"),M32-L32) -> 0
A33: =A23+3 -> 105 | B33: Fr | G33: =IF(OR(ISBLANK(D33),ISBLANK(E33)),0,E33-D33-F33) -> 0 | I33: =IF((G33-C33)<0,TEXT(C33-G33,"-[hh]:mm"),G33-C33) -> 0 | N33: =IF((M33-L33)<0,TEXT(L33-M33,"-[h]:mm"),M33-L33) -> 0
B34: Sonst | G34: =IF(OR(ISBLANK(D34),ISBLANK(E34)),0,E34-D34-F34) -> 0 | I34: =IF((G34-C34)<0,TEXT(C34-G34,"-[hh]:mm"),G34-C34) -> 0 | N34: =IF((M34-L34)<0,TEXT(L34-M34,"-[h]:mm"),M34-L34) -> 0
A35: =IF(A28<>"",A28+1,"") -> 16 | B35: ∑ | C35: =SUM(C29:C34) -> 0 | F35: =SUM(F29:F34) -> 0 | G35: =SUM(G29:G34) -> 0 | I35: =IF((G35-C35+J35)<0,TEXT(C35-G35-J35,"-[h]:mm"),G35-C35+J35) -> 0 | J35: =SUM(J29:J34) -> 0 | K35: =IF(LEFT(K28,1)="-",IF((G35-C35+J35-N6)<0,TEXT(C35-G35-J35+N6,"-[hh]:mm"),G35-C35+J35-N6),IF((G35-C35+J35+N6)<0,TEXT(C35-G35+J35-N6,"-[hh]:mm"),G35-C35+J35+N6)) -> 0 | L35: =SUM(L29:L34) -> 0 | M35: =SUM(M29:M34) -> 0 | N35: =IF((M35-L35)<0,TEXT(L35-M35,"-[h]:mm"),M35-L35) -> 0
B36: ∑ | C36: =C14+C21+C28+C35 -> 0 | G36: =G14+G21+G28+G35 -> 0 | I36: =IF((G36-C36+J36)<0,TEXT(C36-G36-J36,"-[h]:mm"),G36-C36+J36) -> 0 | J36: =J14+J21+J28+J35 -> 0 | K36: =K35 -> 0 | N36: Gesamtstunden = Übertrag auf neues Blatt | Q36: =K36 -> 0
N37: Mehrarbeit in der vierten Woche = Übertrag auf neues Blatt | Q37: =I35 -> 0
A38: U | F38: =TODAY() -> 46019
A39: K | F39: Datum | M39: Unterschrift Mitarbeiter/-in
A40: F
...

Sheet KW 17-20
A1: Arbeitszeiterfassung (Freizeitausgleich) (Dieser Vordruck ist zu verwenden, wenn auf der Erklärung die Option "Freizeitausgleich" angekreuzt wurde)
A2: Name: | C2: =Stammangaben!$B$3 -> 0 | N2: TE | O2: =Stammangaben!B4 -> 0
A3: =IF(NOT(Stammangaben!C7=""),Stammangaben!C7,Stammangaben!C6) -> 0 | B3: Std / Woche | C3: gesamte Arbeitszeit | L3: VZ-Zeiten
C4: Übertrag der Gesamtstunden aus letztem Blatt | I4: ='KW 13-16'!K36 -> 0
C5: Übertrag der Mehrarbeit aus vierter Woche vom letzten Blatt | I5: ='KW 13-16'!I35 -> 0
K6: =IF(LEFT(I4,1)="-",RIGHT(I4,LEN(I4)-1),I4) -> 0 | L6: =IF(LEFT(K14,1)="-",RIGHT(K14,LEN(K14)-1),K14) -> 0 | M6: =IF(LEFT(K21,1)="-",RIGHT(K21,LEN(K21)-1),K21) -> 0 | N6: =IF(LEFT(K28,1)="-",RIGHT(K28,LEN(K28)-1),K28) -> 0
A7: KW | C7: Soll | D7: von | E7: bis | F7: Pause | G7: Ist | H7: U/K/F/AB | I7: Haben/ Woche | J7: AZ aus Bereit-schaft | K7: Haben ges. | L7: Soll | M7: Ist | N7: Haben | O7: außer Haus | P7: Begründung für Abweichung Soll / Ist bei VZ | Q7: bei relevanter Abweichung von der Soll-Arbeitszeit (= mehr als 30 min.) Begründung
B8: Mo | G8: =IF(OR(ISBLANK(D8),ISBLANK(E8)),0,E8-D8-F8) -> 0 | I8: =IF((G8-C8)<0,TEXT(C8-G8,"-[h]:mm"),G8-C8) -> 0 | N8: =IF((M8-L8)<0,TEXT(L8-M8,"-[h]:mm"),M8-L8) -> 0
A9: =A12+4 -> 116 | B9: Di | G9: =IF(OR(ISBLANK(D9),ISBLANK(E9)),0,E9-D9-F9) -> 0 | I9: =IF((G9-C9)<0,TEXT(C9-G9,"-[h]:mm"),G9-C9) -> 0 | N9: =IF((M9-L9)<0,TEXT(L9-M9,"-[h]:mm"),M9-L9) -> 0
B10: Mi | G10: =IF(OR(ISBLANK(D10),ISBLANK(E10)),0,E10-D10-F10) -> 0 | I10: =IF((G10-C10)<0,TEXT(C10-G10,"-[h]:mm"),G10-C10) -> 0 | N10: =IF((M10-L10)<0,TEXT(L10-M10,"-[h]:mm"),M10-L10) -> 0
A11: - | B11: Do | G11: =IF(OR(ISBLANK(D11),ISBLANK(E11)),0,E11-D11-F11) -> 0 | I11: =IF((G11-C11)<0,TEXT(C11-G11,"-[h]:mm"),G11-C11) -> 0 | N11: =IF((M11-L11)<0,TEXT(L11-M11,"-[h]:mm"),M11-L11) -> 0
A12: ='KW 13-16'!A30+3 -> 112 | B12: Fr | G12: =IF(OR(ISBLANK(D12),ISBLANK(E12)),0,E12-D12-F12) -> 0 | I12: =IF((G12-C12)<0,TEXT(C12-G12,"-[h]:mm"),G12-C12) -> 0 | N12: =IF((M12-L12)<0,TEXT(L12-M12,"-[h]:mm"),M12-L12) -> 0
B13: Sonst | G13: =IF(OR(ISBLANK(D13),ISBLANK(E13)),0,E13-D13-F13) -> 0 | I13: =IF((G13-C13)<0,TEXT(C13-G13,"-[h]:mm"),G13-C13) -> 0 | N13: =IF((M13-L13)<0,TEXT(L13-M13,"-[h]:mm"),M13-L13) -> 0
A14: ='KW 13-16'!A35+1 -> 17 | B14: ∑ | C14: =SUM(C8:C13) -> 0 | G14: =SUM(G8:G13) -> 0 | I14: =IF((G14-C14+J14)<0,TEXT(C14-G14-J14,"-[h]:mm"),G14-C14+J14) -> 0 | J14: =SUM(J8:J13) -> 0 | K14: =IF(LEFT(I4,1)="-",IF((G14-C14+J14-K6)<0,TEXT(C14-G14-J14+K6,"-[hh]:mm"),G14-C14+J14-K6),IF((G14-C14+J14+K6)<0,TEXT(C14-G14+J14-K6,"-[hh]:mm"),G14-C14+J14+K6)) -> 0 | L14: =SUM(L8:L13) -> 0 | M14: =SUM(M8:M13) -> 0 | N14: =IF((M14-L14)<0,TEXT(L14-M14,"-[h]:mm"),M14-L14) -> 0
B15: Mo | G15: =IF(OR(ISBLANK(D15),ISBLANK(E15)),0,E15-D15-F15) -> 0 | I15: =IF((G15-C15)<0,TEXT(C15-G15,"-[h]:mm"),G15-C15) -> 0 | N15: =IF((M15-L15)<0,TEXT(L15-M15,"-[h]:mm"),M15-L15) -> 0
A16: =A19+4 -> 123 | B16: Di | G16: =IF(OR(ISBLANK(D16),ISBLANK(E16)),0,E16-D16-F16) -> 0 | I16: =IF((G16-C16)<0,TEXT(C16-G16,"-[h]:mm"),G16-C16) -> 0 | N16: =IF((M16-L16)<0,TEXT(L16-M16,"-[h]:mm"),M16-L16) -> 0
B17: Mi | G17: =IF(OR(ISBLANK(D17),ISBLANK(E17)),0,E17-D17-F17) -> 0 | I17: =IF((G17-C17)<0,TEXT(C17-G17,"-[h]:mm"),G17-C17) -> 0 | N17: =IF((M17-L17)<0,TEXT(L17-M17,"-[h]:mm"),M17-L17) -> 0
A18: - | B18: Do | G18: =IF(OR(ISBLANK(D18),ISBLANK(E18)),0,E18-D18-F18) -> 0 | I18: =IF((G18-C18)<0,TEXT(C18-G18,"-[h]:mm"),G18-C18) -> 0 | N18: =IF((M18-L18)<0,TEXT(L18-M18,"-[h]:mm"),M18-L18) -> 0
A19: =A9+3 -> 119 | B19: Fr | G19: =IF(OR(ISBLANK(D19),ISBLANK(E19)),0,E19-D19-F19) -> 0 | I19: =IF((G19-C19)<0,TEXT(C19-G19,"-[h]:mm"),G19-C19) -> 0 | N19: =IF((M19-L19)<0,TEXT(L19-M19,"-[h]:mm"),M19-L19) -> 0
B20: Sonst | G20: =E20-D20-F20 -> 0 | I20: =IF((G20-C20)<0,TEXT(C20-G20,"-[h]:mm"),G20-C20) -> 0 | N20: =IF((M20-L20)<0,TEXT(L20-M20,"-[h]:mm"),M20-L20) -> 0
A21: =IF(A14<>"",A14+1,"") -> 18 | B21: ∑ | C21: =SUM(C15:C20) -> 0 | G21: =SUM(G15:G20) -> 0 | I21: =IF((G21-C21+J21)<0,TEXT(C21-G21-J21,"-[h]:mm"),G21-C21+J21) -> 0 | J21: =SUM(J15:J20) -> 0 | K21: =IF(LEFT(K14,1)="-",IF((G21-C21+J21-L6)<0,TEXT(C21-G21-J21+L6,"-[hh]:mm"),G21-C21+J21-L6),IF((G21-C21+J21+L6)<0,TEXT(C21-G21+J21-L6,"-[hh]:mm"),G21-C21+J21+L6)) -> 0 | L21: =SUM(L15:L20) -> 0 | M21: =SUM(M15:M20) -> 0 | N21: =IF((M21-L21)<0,TEXT(L21-M21,"-[h]:mm"),M21-L21) -> 0
B22: Mo | G22: =IF(OR(ISBLANK(D22),ISBLANK(E22)),0,E22-D22-F22) -> 0 | I22: =IF((G22-C22)<0,TEXT(C22-G22,"-[h]:mm"),G22-C22) -> 0 | N22: =IF((M22-L22)<0,TEXT(L22-M22,"-[h]:mm"),M22-L22) -> 0
A23: =A26+4 -> 130 | B23: Di | G23: =IF(OR(ISBLANK(D23),ISBLANK(E23)),0,E23-D23-F23) -> 0 | I23: =IF((G23-C23)<0,TEXT(C23-G23,"-[h]:mm"),G23-C23) -> 0 | N23: =IF((M23-L23)<0,TEXT(L23-M23,"-[h]:mm"),M23-L23) -> 0
B24: Mi | G24: =IF(OR(ISBLANK(D24),ISBLANK(E24)),0,E24-D24-F24) -> 0 | I24: =IF((G24-C24)<0,TEXT(C24-G24,"-[h]:mm"),G24-C24) -> 0 | N24: =IF((M24-L24)<0,TEXT(L24-M24,"-[h]:mm"),M24-L24) -> 0
A25: - | B25: Do | G25: =IF(OR(ISBLANK(D25),ISBLANK(E25)),0,E25-D25-F25) -> 0 | I25: =IF((G25-C25)<0,TEXT(C25-G25,"-[h]:mm"),G25-C25) -> 0 | N25: =IF((M25-L25)<0,TEXT(L25-M25,"-[h]:mm"),M25-L25) -> 0
A26: =A16+3 -> 126 | B26: Fr | G26: =IF(OR(ISBLANK(D26),ISBLANK(E26)),0,E26-D26-F26) -> 0 | I26: =IF((G26-C26)<0,TEXT(C26-G26,"-[h]:mm"),G26-C26) -> 0 | N26: =IF((M26-L26)<0,TEXT(L26-M26,"-[h]:mm"),M26-L26) -> 0
B27: Sonst | G27: =IF(OR(ISBLANK(D27),ISBLANK(E27)),0,E27-D27-F27) -> 0 | I27: =IF((G27-C27)<0,TEXT(C27-G27,"-[h]:mm"),G27-C27) -> 0 | N27: =IF((M27-L27)<0,TEXT(L27-M27,"-[h]:mm"),M27-L27) -> 0
A28: =IF(A21<>"",A21+1,"") -> 19 | B28: ∑ | C28: =SUM(C22:C27) -> 0 | G28: =SUM(G22:G27) -> 0 | I28: =IF((G28-C28+J28)<0,TEXT(C28-G28-J28,"-[h]:mm"),G28-C28+J28) -> 0 | J28: =SUM(J22:J27) -> 0 | K28: =IF(LEFT(K21,1)="-",IF((G28-C28+J28-M6)<0,TEXT(C28-G28-J28+M6,"-[hh]:mm"),G28-C28+J28-M6),IF((G28-C28+J28+M6)<0,TEXT(C28-G28+J28-M6,"-[hh]:mm"),G28-C28+J28+M6)) -> 0 | L28: =SUM(L22:L27) -> 0 | M28: =SUM(M22:M27) -> 0 | N28: =IF((M28-L28)<0,TEXT(L28-M28,"-[h]:mm"),M28-L28) -> 0
B29: Mo | G29: =IF(OR(ISBLANK(D29),ISBLANK(E29)),0,E29-D29-F29) -> 0 | I29: =IF((G29-C29)<0,TEXT(C29-G29,"-[h]:mm"),G29-C29) -> 0 | N29: =IF((M29-L29)<0,TEXT(L29-M29,"-[h]:mm"),M29-L29) -> 0
A30: =A33+4 -> 137 | B30: Di | G30: =IF(OR(ISBLANK(D30),ISBLANK(E30)),0,E30-D30-F30) -> 0 | I30: =IF((G30-C30)<0,TEXT(C30-G30,"-[h]:mm"),G30-C30) -> 0 | N30: =IF((M30-L30)<0,TEXT(L30-M30,"-[h]:mm"),M30-L30) -> 0
B31: Mi | G31: =IF(OR(ISBLANK(D31),ISBLANK(E31)),0,E31-D31-F31) -> 0 | I31: =IF((G31-C31)<0,TEXT(C31-G31,"-[h]:mm"),G31-C31) -> 0 | N31: =IF((M31-L31)<0,TEXT(L31-M31,"-[h]:mm"),M31-L31) -> 0
A32: - | B32: Do | G32: =IF(OR(ISBLANK(D32),ISBLANK(E32)),0,E32-D32-F32) -> 0 | I32: =IF((G32-C32)<0,TEXT(C32-G32,"-[h]:mm"),G32-C32) -> 0 | N32: =IF((M32-L32)<0,TEXT(L32-M32,"-[h]:mm"),M32-L32) -> 0
A33: =A23+3 -> 133 | B33: Fr | G33: =IF(OR(ISBLANK(D33),ISBLANK(E33)),0,E33-D33-F33) -> 0 | I33: =IF((G33-C33)<0,TEXT(C33-G33,"-[hh]:mm"),G33-C33) -> 0 | N33: =IF((M33-L33)<0,TEXT(L33-M33,"-[h]:mm"),M33-L33) -> 0
B34: Sonst | G34: =IF(OR(ISBLANK(D34),ISBLANK(E34)),0,E34-D34-F34) -> 0 | I34: =IF((G34-C34)<0,TEXT(C34-G34,"-[hh]:mm"),G34-C34) -> 0 | N34: =IF((M34-L34)<0,TEXT(L34-M34,"-[h]:mm"),M34-L34) -> 0
A35: =IF(A28<>"",A28+1,"") -> 20 | B35: ∑ | C35: =SUM(C29:C34) -> 0 | F35: =SUM(F29:F34) -> 0 | G35: =SUM(G29:G34) -> 0 | I35: =IF((G35-C35+J35)<0,TEXT(C35-G35-J35,"-[h]:mm"),G35-C35+J35) -> 0 | J35: =SUM(J29:J34) -> 0 | K35: =IF(LEFT(K28,1)="-",IF((G35-C35+J35-N6)<0,TEXT(C35-G35-J35+N6,"-[hh]:mm"),G35-C35+J35-N6),IF((G35-C35+J35+N6)<0,TEXT(C35-G35+J35-N6,"-[hh]:mm"),G35-C35+J35+N6)) -> 0 | L35: =SUM(L29:L34) -> 0 | M35: =SUM(M29:M34) -> 0 | N35: =IF((M35-L35)<0,TEXT(L35-M35,"-[h]:mm"),M35-L35) -> 0
B36: ∑ | C36: =C14+C21+C28+C35 -> 0 | G36: =G14+G21+G28+G35 -> 0 | I36: =IF((G36-C36+J36)<0,TEXT(C36-G36-J36,"-[h]:mm"),G36-C36+J36) -> 0 | J36: =J14+J21+J28+J35 -> 0 | K36: =K35 -> 0 | N36: Gesamtstunden = Übertrag auf neues Blatt | Q36: =K36 -> 0
N37: Mehrarbeit in der vierten Woche = Übertrag auf neues Blatt | Q37: =I35 -> 0
A38: U | F38: =TODAY() -> 46019
A39: K | F39: Datum | M39: Unterschrift Mitarbeiter/-in
A40: F
...

Sheet KW 21-24
A1: Arbeitszeiterfassung (Freizeitausgleich) (Dieser Vordruck ist zu verwenden, wenn auf der Erklärung die Option "Freizeitausgleich" angekreuzt wurde)
A2: Name: | C2: =Stammangaben!$B$3 -> 0 | N2: TE | O2: =Stammangaben!B4 -> 0
A3: =IF(NOT(Stammangaben!C7=""),Stammangaben!C7,Stammangaben!C6) -> 0 | B3: Std / Woche | C3: gesamte Arbeitszeit | L3: VZ-Zeiten
C4: Übertrag der Gesamtstunden aus letztem Blatt | I4: ='KW 17-20'!K36 -> 0
C5: Übertrag der Mehrarbeit aus vierter Woche vom letzten Blatt | I5: ='KW 17-20'!I35 -> 0
K6: =IF(LEFT(I4,1)="-",RIGHT(I4,LEN(I4)-1),I4) -> 0 | L6: =IF(LEFT(K14,1)="-",RIGHT(K14,LEN(K14)-1),K14) -> 0 | M6: =IF(LEFT(K21,1)="-",RIGHT(K21,LEN(K21)-1),K21) -> 0 | N6: =IF(LEFT(K28,1)="-",RIGHT(K28,LEN(K28)-1),K28) -> 0
A7: KW | C7: Soll | D7: von | E7: bis | F7: Pause | G7: Ist | H7: U/K/F/AB | I7: Haben/ Woche | J7: AZ aus Bereit-schaft | K7: Haben ges. | L7: Soll | M7: Ist | N7: Haben | O7: außer Haus | P7: Begründung für Abweichung Soll / Ist bei VZ | Q7: bei relevanter Abweichung von der Soll-Arbeitszeit (= mehr als 30 min.) Begründung
B8: Mo | G8: =IF(OR(ISBLANK(D8),ISBLANK(E8)),0,E8-D8-F8) -> 0 | I8: =IF((G8-C8)<0,TEXT(C8-G8,"-[h]:mm"),G8-C8) -> 0 | N8: =IF((M8-L8)<0,TEXT(L8-M8,"-[h]:mm"),M8-L8) -> 0
A9: =A12+4 -> 144 | B9: Di | G9: =IF(OR(ISBLANK(D9),ISBLANK(E9)),0,E9-D9-F9) -> 0 | I9: =IF((G9-C9)<0,TEXT(C9-G9,"-[h]:mm"),G9-C9) -> 0 | N9: =IF((M9-L9)<0,TEXT(L9-M9,"-[h]:mm"),M9-L9) -> 0
B10: Mi | G10: =IF(OR(ISBLANK(D10),ISBLANK(E10)),0,E10-D10-F10) -> 0 | I10: =IF((G10-C10)<0,TEXT(C10-G10,"-[h]:mm"),G10-C10) -> 0 | N10: =IF((M10-L10)<0,TEXT(L10-M10,"-[h]:mm"),M10-L10) -> 0
A11: - | B11: Do | G11: =IF(OR(ISBLANK(D11),ISBLANK(E11)),0,E11-D11-F11) -> 0 | I11: =IF((G11-C11)<0,TEXT(C11-G11,"-[h]:mm"),G11-C11) -> 0 | N11: =IF((M11-L11)<0,TEXT(L11-M11,"-[h]:mm"),M11-L11) -> 0
A12: ='KW 17-20'!A30+3 -> 140 | B12: Fr | G12: =IF(OR(ISBLANK(D12),ISBLANK(E12)),0,E12-D12-F12) -> 0 | I12: =IF((G12-C12)<0,TEXT(C12-G12,"-[h]:mm"),G12-C12) -> 0 | N12: =IF((M12-L12)<0,TEXT(L12-M12,"-[h]:mm"),M12-L12) -> 0
B13: Sonst | G13: =IF(OR(ISBLANK(D13),ISBLANK(E13)),0,E13-D13-F13) -> 0 | I13: =IF((G13-C13)<0,TEXT(C13-G13,"-[h]:mm"),G13-C13) -> 0 | N13: =IF((M13-L13)<0,TEXT(L13-M13,"-[h]:mm"),M13-L13) -> 0
A14: ='KW 17-20'!A35+1 -> 21 | B14: ∑ | C14: =SUM(C8:C13) -> 0 | F14: =SUM(F8:F13) -> 0 | G14: =SUM(G8:G13) -> 0 | I14: =IF((G14-C14+J14)<0,TEXT(C14-G14-J14,"-[h]:mm"),G14-C14+J14) -> 0 | J14: =SUM(J8:J13) -> 0 | K14: =IF(LEFT(I4,1)="-",IF((G14-C14+J14-K6)<0,TEXT(C14-G14-J14+K6,"-[hh]:mm"),G14-C14+J14-K6),IF((G14-C14+J14+K6)<0,TEXT(C14-G14+J14-K6,"-[hh]:mm"),G14-C14+J14+K6)) -> 0 | L14: =SUM(L8:L13) -> 0 | M14: =SUM(M8:M13) -> 0 | N14: =IF((M14-L14)<0,TEXT(L14-M14,"-[h]:mm"),M14-L14) -> 0
B15: Mo | G15: =IF(OR(ISBLANK(D15),ISBLANK(E15)),0,E15-D15-F15) -> 0 | I15: =IF((G15-C15)<0,TEXT(C15-G15,"-[h]:mm"),G15-C15) -> 0 | N15: =IF((M15-L15)<0,TEXT(L15-M15,"-[h]:mm"),M15-L15) -> 0
A16: =A19+4 -> 151 | B16: Di | G16: =IF(OR(ISBLANK(D16),ISBLANK(E16)),0,E16-D16-F16) -> 0 | I16: =IF((G16-C16)<0,TEXT(C16-G16,"-[h]:mm"),G16-C16) -> 0 | N16: =IF((M16-L16)<0,TEXT(L16-M16,"-[h]:mm"),M16-L16) -> 0
B17: Mi | G17: =IF(OR(ISBLANK(D17),ISBLANK(E17)),0,E17-D17-F17) -> 0 | I17: =IF((G17-C17)<0,TEXT(C17-G17,"-[h]:mm"),G17-C17) -> 0 | N17: =IF((M17-L17)<0,TEXT(L17-M17,"-[h]:mm"),M17-L17) -> 0
A18: - | B18: Do | G18: =IF(OR(ISBLANK(D18),ISBLANK(E18)),0,E18-D18-F18) -> 0 | I18: =IF((G18-C18)<0,TEXT(C18-G18,"-[h]:mm"),G18-C18) -> 0 | N18: =IF((M18-L18)<0,TEXT(L18-M18,"-[h]:mm"),M18-L18) -> 0
A19: =A9+3 -> 147 | B19: Fr | G19: =IF(OR(ISBLANK(D19),ISBLANK(E19)),0,E19-D19-F19) -> 0 | I19: =IF((G19-C19)<0,TEXT(C19-G19,"-[h]:mm"),G19-C19) -> 0 | N19: =IF((M19-L19)<0,TEXT(L19-M19,"-[h]:mm"),M19-L19) -> 0
B20: Sonst | G20: =E20-D20-F20 -> 0 | I20: =IF((G20-C20)<0,TEXT(C20-G20,"-[h]:mm"),G20-C20) -> 0 | N20: =IF((M20-L20)<0,TEXT(L20-M20,"-[h]:mm"),M20-L20) -> 0
A21: =IF(A14<>"",A14+1,"") -> 22 | B21: ∑ | C21: =SUM(C15:C20) -> 0 | F21: =SUM(F15:F20) -> 0 | G21: =SUM(G15:G20) -> 0 | I21: =IF((G21-C21+J21)<0,TEXT(C21-G21-J21,"-[h]:mm"),G21-C21+J21) -> 0 | J21: =SUM(J15:J20) -> 0 | K21: =IF(LEFT(K14,1)="-",IF((G21-C21+J21-L6)<0,TEXT(C21-G21-J21+L6,"-[hh]:mm"),G21-C21+J21-L6),IF((G21-C21+J21+L6)<0,TEXT(C21-G21+J21-L6,"-[hh]:mm"),G21-C21+J21+L6)) -> 0 | L21: =SUM(L15:L20) -> 0 | M21: =SUM(M15:M20) -> 0 | N21: =IF((M21-L21)<0,TEXT(L21-M21,"-[h]:mm"),M21-L21) -> 0
B22: Mo | G22: =IF(OR(ISBLANK(D22),ISBLANK(E22)),0,E22-D22-F22) -> 0 | I22: =IF((G22-C22)<0,TEXT(C22-G22,"-[h]:mm"),G22-C22) -> 0 | N22: =IF((M22-L22)<0,TEXT(L22-M22,"-[h]:mm"),M22-L22) -> 0
A23: =A26+4 -> 158 | B23: Di | G23: =IF(OR(ISBLANK(D23),ISBLANK(E23)),0,E23-D23-F23) -> 0 | I23: =IF((G23-C23)<0,TEXT(C23-G23,"-[h]:mm"),G23-C23) -> 0 | N23: =IF((M23-L23)<0,TEXT(L23-M23,"-[h]:mm"),M23-L23) -> 0
B24: Mi | G24: =IF(OR(ISBLANK(D24),ISBLANK(E24)),0,E24-D24-F24) -> 0 | I24: =IF((G24-C24)<0,TEXT(C24-G24,"-[h]:mm"),G24-C24) -> 0 | N24: =IF((M24-L24)<0,TEXT(L24-M24,"-[h]:mm"),M24-L24) -> 0
A25: - | B25: Do | G25: =IF(OR(ISBLANK(D25),ISBLANK(E25)),0,E25-D25-F25) -> 0 | I25: =IF((G25-C25)<0,TEXT(C25-G25,"-[h]:mm"),G25-C25) -> 0 | N25: =IF((M25-L25)<0,TEXT(L25-M25,"-[h]:mm"),M25-L25) -> 0
A26: =A16+3 -> 154 | B26: Fr | G26: =IF(OR(ISBLANK(D26),ISBLANK(E26)),0,E26-D26-F26) -> 0 | I26: =IF((G26-C26)<0,TEXT(C26-G26,"-[h]:mm"),G26-C26) -> 0 | N26: =IF((M26-L26)<0,TEXT(L26-M26,"-[h]:mm"),M26-L26) -> 0
B27: Sonst | G27: =IF(OR(ISBLANK(D27),ISBLANK(E27)),0,E27-D27-F27) -> 0 | I27: =IF((G27-C27)<0,TEXT(C27-G27,"-[h]:mm"),G27-C27) -> 0 | N27: =IF((M27-L27)<0,TEXT(L27-M27,"-[h]:mm"),M27-L27) -> 0
A28: =IF(A21<>"",A21+1,"") -> 23 | B28: ∑ | C28: =SUM(C22:C27) -> 0 | F28: =SUM(F22:F27) -> 0 | G28: =SUM(G22:G27) -> 0 | I28: =IF((G28-C28+J28)<0,TEXT(C28-G28-J28,"-[h]:mm"),G28-C28+J28) -> 0 | J28: =SUM(J22:J27) -> 0 | K28: =IF(LEFT(K21,1)="-",IF((G28-C28+J28-M6)<0,TEXT(C28-G28-J28+M6,"-[hh]:mm"),G28-C28+J28-M6),IF((G28-C28+J28+M6)<0,TEXT(C28-G28+J28-M6,"-[hh]:mm"),G28-C28+J28+M6)) -> 0 | L28: =SUM(L22:L27) -> 0 | M28: =SUM(M22:M27) -> 0 | N28: =IF((M28-L28)<0,TEXT(L28-M28,"-[h]:mm"),M28-L28) -> 0
B29: Mo | G29: =IF(OR(ISBLANK(D29),ISBLANK(E29)),0,E29-D29-F29) -> 0 | I29: =IF((G29-C29)<0,TEXT(C29-G29,"-[h]:mm"),G29-C29) -> 0 | N29: =IF((M29-L29)<0,TEXT(L29-M29,"-[h]:mm"),M29-L29) -> 0
A30: =A33+4 -> 165 | B30: Di | G30: =IF(OR(ISBLANK(D30),ISBLANK(E30)),0,E30-D30-F30) -> 0 | I30: =IF((G30-C30)<0,TEXT(C30-G30,"-[h]:mm"),G30-C30) -> 0 | N30: =IF((M30-L30)<0,TEXT(L30-M30,"-[h]:mm"),M30-L30) -> 0
B31: Mi | G31: =IF(OR(ISBLANK(D31),ISBLANK(E31)),0,E31-D31-F31) -> 0 | I31: =IF((G31-C31)<0,TEXT(C31-G31,"-[h]:mm"),G31-C31) -> 0 | N31: =IF((M31-L31)<0,TEXT(L31-M31,"-[h]:mm"),M31-L31) -> 0
A32: - | B32: Do | G32: =IF(OR(ISBLANK(D32),ISBLANK(E32)),0,E32-D32-F32) -> 0 | I32: =IF((G32-C32)<0,TEXT(C32-G32,"-[h]:mm"),G32-C32) -> 0 | N32: =IF((M32-L32)<0,TEXT(L32-M32,"-[h]:mm"),M32-L32) -> 0
A33: =A23+3 -> 161 | B33: Fr | G33: =IF(OR(ISBLANK(D33),ISBLANK(E33)),0,E33-D33-F33) -> 0 | I33: =IF((G33-C33)<0,TEXT(C33-G33,"-[hh]:mm"),G33-C33) -> 0 | N33: =IF((M33-L33)<0,TEXT(L33-M33,"-[h]:mm"),M33-L33) -> 0
B34: Sonst | G34: =IF(OR(ISBLANK(D34),ISBLANK(E34)),0,E34-D34-F34) -> 0 | I34: =IF((G34-C34)<0,TEXT(C34-G34,"-[hh]:mm"),G34-C34) -> 0 | N34: =IF((M34-L34)<0,TEXT(L34-M34,"-[h]:mm"),M34-L34) -> 0
A35: =IF(A28<>"",A28+1,"") -> 24 | B35: ∑ | C35: =SUM(C29:C34) -> 0 | F35: =SUM(F29:F34) -> 0 | G35: =SUM(G29:G34) -> 0 | I35: =IF((G35-C35+J35)<0,TEXT(C35-G35-J35,"-[h]:mm"),G35-C35+J35) -> 0 | J35: =SUM(J29:J34) -> 0 | K35: =IF(LEFT(K28,1)="-",IF((G35-C35+J35-N6)<0,TEXT(C35-G35-J35+N6,"-[hh]:mm"),G35-C35+J35-N6),IF((G35-C35+J35+N6)<0,TEXT(C35-G35+J35-N6,"-[hh]:mm"),G35-C35+J35+N6)) -> 0 | L35: =SUM(L29:L34) -> 0 | M35: =SUM(M29:M34) -> 0 | N35: =IF((M35-L35)<0,TEXT(L35-M35,"-[h]:mm"),M35-L35) -> 0
B36: ∑ | C36: =C14+C21+C28+C35 -> 0 | G36: =G14+G21+G28+G35 -> 0 | I36: =IF((G36-C36+J36)<0,TEXT(C36-G36-J36,"-[h]:mm"),G36-C36+J36) -> 0 | J36: =J14+J21+J28+J35 -> 0 | K36: =K35 -> 0 | N36: Gesamtstunden = Übertrag auf neues Blatt | Q36: =K36 -> 0
N37: Mehrarbeit in der vierten Woche = Übertrag auf neues Blatt | Q37: =I35 -> 0
A38: U | F38: =TODAY() -> 46019
A39: K | F39: Datum | M39: Unterschrift Mitarbeiter/-in
A40: F
...

Sheet KW 25-28
A1: Arbeitszeiterfassung (Freizeitausgleich) (Dieser Vordruck ist zu verwenden, wenn auf der Erklärung die Option "Freizeitausgleich" angekreuzt wurde)
A2: Name: | C2: =Stammangaben!$B$3 -> 0 | N2: TE | O2: =Stammangaben!B4 -> 0
A3: =IF(NOT(Stammangaben!C7=""),Stammangaben!C7,Stammangaben!C6) -> 0 | B3: Std / Woche | C3: gesamte Arbeitszeit | L3: VZ-Zeiten
C4: Übertrag der Gesamtstunden aus letztem Blatt | I4: ='KW 21-24'!K36 -> 0
C5: Übertrag der Mehrarbeit aus vierter Woche vom letzten Blatt | I5: ='KW 21-24'!I35 -> 0
K6: =IF(LEFT(I4,1)="-",RIGHT(I4,LEN(I4)-1),I4) -> 0 | L6: =IF(LEFT(K14,1)="-",RIGHT(K14,LEN(K14)-1),K14) -> 0 | M6: =IF(LEFT(K21,1)="-",RIGHT(K21,LEN(K21)-1),K21) -> 0 | N6: =IF(LEFT(K28,1)="-",RIGHT(K28,LEN(K28)-1),K28) -> 0
A7: KW | C7: Soll | D7: von | E7: bis | F7: Pause | G7: Ist | H7: U/K/F/AB | I7: Haben/ Woche | J7: AZ aus Bereit-schaft | K7: Haben ges. | L7: Soll | M7: Ist | N7: Haben | O7: außer Haus | P7: Begründung für Abweichung Soll / Ist bei VZ | Q7: bei relevanter Abweichung von der Soll-Arbeitszeit (= mehr als 30 min.) Begründung
B8: Mo | G8: =IF(OR(ISBLANK(D8),ISBLANK(E8)),0,E8-D8-F8) -> 0 | I8: =IF((G8-C8)<0,TEXT(C8-G8,"-[h]:mm"),G8-C8) -> 0 | N8: =IF((M8-L8)<0,TEXT(L8-M8,"-[h]:mm"),M8-L8) -> 0
A9: =A12+4 -> 172 | B9: Di | G9: =IF(OR(ISBLANK(D9),ISBLANK(E9)),0,E9-D9-F9) -> 0 | I9: =IF((G9-C9)<0,TEXT(C9-G9,"-[h]:mm"),G9-C9) -> 0 | N9: =IF((M9-L9)<0,TEXT(L9-M9,"-[h]:mm"),M9-L9) -> 0
B10: Mi | G10: =IF(OR(ISBLANK(D10),ISBLANK(E10)),0,E10-D10-F10) -> 0 | I10: =IF((G10-C10)<0,TEXT(C10-G10,"-[h]:mm"),G10-C10) -> 0 | N10: =IF((M10-L10)<0,TEXT(L10-M10,"-[h]:mm"),M10-L10) -> 0
A11: - | B11: Do | G11: =IF(OR(ISBLANK(D11),ISBLANK(E11)),0,E11-D11-F11) -> 0 | I11: =IF((G11-C11)<0,TEXT(C11-G11,"-[h]:mm"),G11-C11) -> 0 | N11: =IF((M11-L11)<0,TEXT(L11-M11,"-[h]:mm"),M11-L11) -> 0
A12: ='KW 21-24'!A30+3 -> 168 | B12: Fr | G12: =IF(OR(ISBLANK(D12),ISBLANK(E12)),0,E12-D12-F12) -> 0 | I12: =IF((G12-C12)<0,TEXT(C12-G12,"-[h]:mm"),G12-C12) -> 0 | N12: =IF((M12-L12)<0,TEXT(L12-M12,"-[h]:mm"),M12-L12) -> 0
B13: Sonst | G13: =IF(OR(ISBLANK(D13),ISBLANK(E13)),0,E13-D13-F13) -> 0 | I13: =IF((G13-C13)<0,TEXT(C13-G13,"-[h]:mm"),G13-C13) -> 0 | N13: =IF((M13-L13)<0,TEXT(L13-M13,"-[h]:mm"),M13-L13) -> 0
A14: ='KW 21-24'!A35+1 -> 25 | B14: ∑ | C14: =SUM(C8:C13) -> 0 | F14: =SUM(F8:F13) -> 0 | G14: =SUM(G8:G13) -> 0 | I14: =IF((G14-C14+J14)<0,TEXT(C14-G14-J14,"-[h]:mm"),G14-C14+J14) -> 0 | J14: =SUM(J8:J13) -> 0 | K14: =IF(LEFT(I4,1)="-",IF((G14-C14+J14-K6)<0,TEXT(C14-G14-J14+K6,"-[hh]:mm"),G14-C14+J14-K6),IF((G14-C14+J14+K6)<0,TEXT(C14-G14+J14-K6,"-[hh]:mm"),G14-C14+J14+K6)) -> 0 | L14: =SUM(L8:L13) -> 0 | M14: =SUM(M8:M13) -> 0 | N14: =IF((M14-L14)<0,TEXT(L14-M14,"-[h]:mm"),M14-L14) -> 0
B15: Mo | G15: =IF(OR(ISBLANK(D15),ISBLANK(E15)),0,E15-D15-F15) -> 0 | I15: =IF((G15-C15)<0,TEXT(C15-G15,"-[h]:mm"),G15-C15) -> 0 | N15: =IF((M15-L15)<0,TEXT(L15-M15,"-[h]:mm"),M15-L15) -> 0
A16: =A19+4 -> 179 | B16: Di | G16: =IF(OR(ISBLANK(D16),ISBLANK(E16)),0,E16-D16-F16) -> 0 | I16: =IF((G16-C16)<0,TEXT(C16-G16,"-[h]:mm"),G16-C16) -> 0 | N16: =IF((M16-L16)<0,TEXT(L16-M16,"-[h]:mm"),M16-L16) -> 0
B17: Mi | G17: =IF(OR(ISBLANK(D17),ISBLANK(E17)),0,E17-D17-F17) -> 0 | I17: =IF((G17-C17)<0,TEXT(C17-G17,"-[h]:mm"),G17-C17) -> 0 | N17: =IF((M17-L17)<0,TEXT(L17-M17,"-[h]:mm"),M17-L17) -> 0
A18: - | B18: Do | G18: =IF(OR(ISBLANK(D18),ISBLANK(E18)),0,E18-D18-F18) -> 0 | I18: =IF((G18-C18)<0,TEXT(C18-G18,"-[h]:mm"),G18-C18) -> 0 | N18: =IF((M18-L18)<0,TEXT(L18-M18,"-[h]:mm"),M18-L18) -> 0
A19: =A9+3 -> 175 | B19: Fr | G19: =IF(OR(ISBLANK(D19),ISBLANK(E19)),0,E19-D19-F19) -> 0 | I19: =IF((G19-C19)<0,TEXT(C19-G19,"-[h]:mm"),G19-C19) -> 0 | N19: =IF((M19-L19)<0,TEXT(L19-M19,"-[h]:mm"),M19-L19) -> 0
B20: Sonst | G20: =E20-D20-F20 -> 0 | I20: =IF((G20-C20)<0,TEXT(C20-G20,"-[h]:mm"),G20-C20) -> 0 | N20: =IF((M20-L20)<0,TEXT(L20-M20,"-[h]:mm"),M20-L20) -> 0
A21: =IF(A14<>"",A14+1,"") -> 26 | B21: ∑ | C21: =SUM(C15:C20) -> 0 | F21: =SUM(F15:F20) -> 0 | G21: =SUM(G15:G20) -> 0 | I21: =IF((G21-C21+J21)<0,TEXT(C21-G21-J21,"-[h]:mm"),G21-C21+J21) -> 0 | J21: =SUM(J15:J20) -> 0 | K21: =IF(LEFT(K14,1)="-",IF((G21-C21+J21-L6)<0,TEXT(C21-G21-J21+L6,"-[hh]:mm"),G21-C21+J21-L6),IF((G21-C21+J21+L6)<0,TEXT(C21-G21+J21-L6,"-[hh]:mm"),G21-C21+J21+L6)) -> 0 | L21: =SUM(L15:L20) -> 0 | M21: =SUM(M15:M20) -> 0 | N21: =IF((M21-L21)<0,TEXT(L21-M21,"-[h]:mm"),M21-L21) -> 0
B22: Mo | G22: =IF(OR(ISBLANK(D22),ISBLANK(E22)),0,E22-D22-F22) -> 0 | I22: =IF((G22-C22)<0,TEXT(C22-G22,"-[h]:mm"),G22-C22) -> 0 | N22: =IF((M22-L22)<0,TEXT(L22-M22,"-[h]:mm"),M22-L22) -> 0
A23: =A26+4 -> 186 | B23: Di | G23: =IF(OR(ISBLANK(D23),ISBLANK(E23)),0,E23-D23-F23) -> 0 | I23: =IF((G23-C23)<0,TEXT(C23-G23,"-[h]:mm"),G23-C23) -> 0 | N23: =IF((M23-L23)<0,TEXT(L23-M23,"-[h]:mm"),M23-L23) -> 0
B24: Mi | G24: =IF(OR(ISBLANK(D24),ISBLANK(E24)),0,E24-D24-F24) -> 0 | I24: =IF((G24-C24)<0,TEXT(C24-G24,"-[h]:mm"),G24-C24) -> 0 | N24: =IF((M24-L24)<0,TEXT(L24-M24,"-[h]:mm"),M24-L24) -> 0
A25: - | B25: Do | G25: =IF(OR(ISBLANK(D25),ISBLANK(E25)),0,E25-D25-F25) -> 0 | I25: =IF((G25-C25)<0,TEXT(C25-G25,"-[h]:mm"),G25-C25) -> 0 | N25: =IF((M25-L25)<0,TEXT(L25-M25,"-[h]:mm"),M25-L25) -> 0
A26: =A16+3 -> 182 | B26: Fr | G26: =IF(OR(ISBLANK(D26),ISBLANK(E26)),0,E26-D26-F26) -> 0 | I26: =IF((G26-C26)<0,TEXT(C26-G26,"-[h]:mm"),G26-C26) -> 0 | N26: =IF((M26-L26)<0,TEXT(L26-M26,"-[h]:mm"),M26-L26) -> 0
B27: Sonst | G27: =IF(OR(ISBLANK(D27),ISBLANK(E27)),0,E27-D27-F27) -> 0 | I27: =IF((G27-C27)<0,TEXT(C27-G27,"-[h]:mm"),G27-C27) -> 0 | N27: =IF((M27-L27)<0,TEXT(L27-M27,"-[h]:mm"),M27-L27) -> 0
A28: =IF(A21<>"",A21+1,"") -> 27 | B28: ∑ | C28: =SUM(C22:C27) -> 0 | F28: =SUM(F22:F27) -> 0 | G28: =SUM(G22:G27) -> 0 | I28: =IF((G28-C28+J28)<0,TEXT(C28-G28-J28,"-[h]:mm"),G28-C28+J28) -> 0 | J28: =SUM(J22:J27) -> 0 | K28: =IF(LEFT(K21,1)="-",IF((G28-C28+J28-M6)<0,TEXT(C28-G28-J28+M6,"-[hh]:mm"),G28-C28+J28-M6),IF((G28-C28+J28+M6)<0,TEXT(C28-G28+J28-M6,"-[hh]:mm"),G28-C28+J28+M6)) -> 0 | L28: =SUM(L22:L27) -> 0 | M28: =SUM(M22:M27) -> 0 | N28: =IF((M28-L28)<0,TEXT(L28-M28,"-[h]:mm"),M28-L28) -> 0
B29: Mo | G29: =IF(OR(ISBLANK(D29),ISBLANK(E29)),0,E29-D29-F29) -> 0 | I29: =IF((G29-C29)<0,TEXT(C29-G29,"-[h]:mm"),G29-C29) -> 0 | N29: =IF((M29-L29)<0,TEXT(L29-M29,"-[h]:mm"),M29-L29) -> 0
A30: =A33+4 -> 193 | B30: Di | G30: =IF(OR(ISBLANK(D30),ISBLANK(E30)),0,E30-D30-F30) -> 0 | I30: =IF((G30-C30)<0,TEXT(C30-G30,"-[h]:mm"),G30-C30) -> 0 | N30: =IF((M30-L30)<0,TEXT(L30-M30,"-[h]:mm"),M30-L30) -> 0
B31: Mi | G31: =IF(OR(ISBLANK(D31),ISBLANK(E31)),0,E31-D31-F31) -> 0 | I31: =IF((G31-C31)<0,TEXT(C31-G31,"-[h]:mm"),G31-C31) -> 0 | N31: =IF((M31-L31)<0,TEXT(L31-M31,"-[h]:mm"),M31-L31) -> 0
A32: - | B32: Do | G32: =IF(OR(ISBLANK(D32),ISBLANK(E32)),0,E32-D32-F32) -> 0 | I32: =IF((G32-C32)<0,TEXT(C32-G32,"-[h]:mm"),G32-C32) -> 0 | N32: =IF((M32-L32)<0,TEXT(L32-M32,"-[h]:mm"),M32-L32) -> 0
A33: =A23+3 -> 189 | B33: Fr | G33: =IF(OR(ISBLANK(D33),ISBLANK(E33)),0,E33-D33-F33) -> 0 | I33: =IF((G33-C33)<0,TEXT(C33-G33,"-[hh]:mm"),G33-C33) -> 0 | N33: =IF((M33-L33)<0,TEXT(L33-M33,"-[h]:mm"),M33-L33) -> 0
B34: Sonst | G34: =IF(OR(ISBLANK(D34),ISBLANK(E34)),0,E34-D34-F34) -> 0 | I34: =IF((G34-C34)<0,TEXT(C34-G34,"-[hh]:mm"),G34-C34) -> 0 | N34: =IF((M34-L34)<0,TEXT(L34-M34,"-[h]:mm"),M34-L34) -> 0
A35: =IF(A28<>"",A28+1,"") -> 28 | B35: ∑ | C35: =SUM(C29:C34) -> 0 | F35: =SUM(F29:F34) -> 0 | G35: =SUM(G29:G34) -> 0 | I35: =IF((G35-C35+J35)<0,TEXT(C35-G35-J35,"-[h]:mm"),G35-C35+J35) -> 0 | J35: =SUM(J29:J34) -> 0 | K35: =IF(LEFT(K28,1)="-",IF((G35-C35+J35-N6)<0,TEXT(C35-G35-J35+N6,"-[hh]:mm"),G35-C35+J35-N6),IF((G35-C35+J35+N6)<0,TEXT(C35-G35+J35-N6,"-[hh]:mm"),G35-C35+J35+N6)) -> 0 | L35: =SUM(L29:L34) -> 0 | M35: =SUM(M29:M34) -> 0 | N35: =IF((M35-L35)<0,TEXT(L35-M35,"-[h]:mm"),M35-L35) -> 0
B36: ∑ | C36: =C14+C21+C28+C35 -> 0 | G36: =G14+G21+G28+G35 -> 0 | I36: =IF((G36-C36+J36)<0,TEXT(C36-G36-J36,"-[h]:mm"),G36-C36+J36) -> 0 | J36: =J14+J21+J28+J35 -> 0 | K36: =K35 -> 0 | N36: Gesamtstunden = Übertrag auf neues Blatt | Q36: =K36 -> 0
N37: Mehrarbeit in der vierten Woche = Übertrag auf neues Blatt | Q37: =I35 -> 0
A38: U | F38: =TODAY() -> 46019
A39: K | F39: Datum | M39: Unterschrift Mitarbeiter/-in
A40: F
...

Sheet KW 29-32
